Workbook

Sheet 光荣榜
A1: 高一年级1801-1820班上学期月考光荣榜 20181017
A2: 理科总分前100名、单科前10名 | P2: 文科总分前50名、单科前10名
A3: 班别 | B3: 姓名 | C3: 总分 | D3: 排名 | F3: 班别 | G3: 姓名 | H3: 语文 | I3: 排名 | K3: 班别 | L3: 姓名 | M3: 物理 | N3: 排名 | P3: 班别 | Q3: 姓名 | R3: 总分 | S3: 排名 | U3: 班级 | V3: 姓名 | W3: 语文 | X3: 排名 | Z3: 班级 | AA3: 姓名 | AB3: 政治 | AC3: 排名
A4: 1814 | B4: 范馨尹 | C4: 671.5 | D4: 1 | F4: 1810 | G4: 徐洋 | H4: 130 | I4: 1 | K4: 1809 | L4: 邹禹盈 | M4: 106 | N4: 1 | P4: 1818 | Q4: 钟妙鸣 | R4: 653.5 | S4: 1 | U4: 1818 | V4: 黄颖珊 | W4: 129 | X4: 1 | Z4: 1818 | AA4: 欧沛杨 | AB4: 98 | AC4: 1
A5: 1809 | B5: 潘黄画意 | C5: 670.5 | D5: 2 | F5: 1803 | G5: 陶芝莹 | H5: 129 | I5: 2 | K5: 1802 | L5: 黎文垚 | M5: 105 | N5: 2 | P5: 1818 | Q5: 欧沛杨 | R5: 641 | S5: 2 | U5: 1818 | V5: 钟妙鸣 | W5: 126 | X5: 2 | Z5: 1818 | AA5: 刘家丽 | AB5: 90 | AC5: 2
A6: 1809 | B6: 黄嘉雨 | C6: 670 | D6: 3 | F6: 1814 | G6: 范馨尹 | H6: 128 | I6: 3 | K6: 1809 | L6: 梁安然 | M6: 104 | N6: 3 | P6: 1818 | Q6: 苏雨昕 | R6: 637.5 | S6: 3 | U6: 1820 | V6: 莫凯茵 | W6: 126 | X6: 2 | Z6: 1818 | AA6: 袁意 | AB6: 89 | AC6: 3
A7: 1801 | B7: 李宗誉 | C7: 667.5 | D7: 4 | F7: 1809 | G7: 冼嘉杏 | H7: 127 | I7: 4 | K7: 1809 | L7: 林聪 | M7: 104 | N7: 3 | P7: 1818 | Q7: 黄颖珊 | R7: 615.5 | S7: 4 | U7: 1818 | V7: 李佳茵 | W7: 124 | X7: 4 | Z7: 1818 | AA7: 钟妙鸣 | AB7: 88 | AC7: 4
A8: 1809 | B8: 邹禹盈 | C8: 664.5 | D8: 5 | F8: 1814 | G8: 冯阳洋 | H8: 127 | I8: 4 | K8: 1811 | L8: 罗晓霖 | M8: 104 | N8: 3 | P8: 1818 | Q8: 刘家丽 | R8: 615 | S8: 5 | U8: 1818 | V8: 黎钊阳 | W8: 123 | X8: 5 | Z8: 1818 | AA8: 车锦红 | AB8: 88 | AC8: 4
A9: 1802 | B9: 黎文垚 | C9: 663.5 | D9: 6 | F9: 1817 | G9: 莫非凡 | H9: 127 | I9: 4 | K9: 1803 | L9: 廖子森 | M9: 104 | N9: 3 | P9: 1818 | Q9: 黎钊阳 | R9: 610 | S9: 6 | U9: 1818 | V9: 谢依君 | W9: 123 | X9: 5 | Z9: 1818 | AA9: 苏雨昕 | AB9: 87 | AC9: 6
A10: 1809 | B10: 陈冠帆 | C10: 663 | D10: 7 | F10: 1809 | G10: 卢奕希 | H10: 127 | I10: 4 | K10: 1809 | L10: 黄嘉雨 | M10: 103 | N10: 7 | P10: 1820 | Q10: 陈洁 | R10: 599 | S10: 7 | U10: 1820 | V10: 谭钰莹 | W10: 122 | X10: 7 | Z10: 1818 | AA10: 曾宪杭 | AB10: 87 | AC10: 6
A11: 1809 | B11: 纪奔妤 | C11: 658 | D11: 8 | F11: 1810 | G11: 韦惠钰 | H11: 127 | I11: 4 | K11: 1816 | L11: 李达昊 | M11: 103 | N11: 7 | P11: 1818 | Q11: 宾颖淇 | R11: 598.5 | S11: 8 | U11: 1820 | V11: 陈洁 | W11: 121 | X11: 8 | Z11: 1819 | AA11: 谢丹妮 | AB11: 87 | AC11: 6
A12: 1809 | B12: 梁安然 | C12: 657.5 | D12: 9 | F12: 1807 | G12: 潘尚 | H12: 127 | I12: 4 | K12: 1808 | L12: 胡永华 | M12: 102 | N12: 9 | P12: 1818 | Q12: 许心愿 | R12: 595.5 | S12: 9 | U12: 1818 | V12: 李诗洋 | W12: 121 | X12: 8 | Z12: 1818 | AA12: 宾颖淇 | AB12: 86 | AC12: 9
A13: 1805 | B13: 何俊锐 | C13: 656 | D13: 10 | F13: 1811 | G13: 周雅婷 | H13: 127 | I13: 4 | K13: 1808 | L13: 黄浩昌 | M13: 102 | N13: 9 | P13: 1818 | Q13: 何希言 | R13: 591.5 | S13: 10 | U13: 1819 | V13: 严颖铧 | W13: 121 | X13: 8 | Z13: 1818 | AA13: 饶幸怡 | AB13: 86 | AC13: 9
A14: 1809 | B14: 潘铭真 | C14: 656 | D14: 10 | K14: 1806 | L14: 陈俊中 | M14: 102 | N14: 9 | P14: 1818 | Q14: 黄麒高 | R14: 578.5 | S14: 11 | U14: 1819 | V14: 李沁睿 | W14: 121 | X14: 8
A15: 1809 | B15: 刘志锋 | C15: 652 | D15: 12 | F15: 班级 | G15: 姓名 | H15: 数学 | I15: 排名 | P15: 1818 | Q15: 李佳茵 | R15: 576.5 | S15: 12
A16: 1813 | B16: 童劲光 | C16: 650 | D16: 13 | F16: 1809 | G16: 梁安然 | H16: 148 | I16: 1 | K16: 班级 | L16: 姓名 | M16: 化学 | N16: 排名 | P16: 1818 | Q16: 李诗洋 | R16: 576 | S16: 13 | U16: 班级 | V16: 姓名 | W16: 数学 | X16: 排名 | Z16: 班级 | AA16: 姓名 | AB16: 历史 | AC16: 排名
A17: 1802 | B17: 覃东健 | C17: 647.5 | D17: 14 | F17: 1801 | G17: 陆嘉杰 | H17: 147 | I17: 2 | K17: 1809 | L17: 梁安然 | M17: 100 | N17: 1 | P17: 1818 | Q17: 黄子聪 | R17: 571 | S17: 14 | U17: 1818 | V17: 刘家丽 | W17: 143 | X17: 1 | Z17: 1818 | AA17: 苏雨昕 | AB17: 96 | AC17: 1
A18: 1809 | B18: 李泳恩 | C18: 647 | D18: 15 | F18: 1803 | G18: 廖子森 | H18: 147 | I18: 2 | K18: 1809 | L18: 黄嘉雨 | M18: 100 | N18: 1 | P18: 1818 | Q18: 关舒心 | R18: 569 | S18: 15 | U18: 1818 | V18: 钟妙鸣 | W18: 142 | X18: 2 | Z18: 1818 | AA18: 欧沛杨 | AB18: 90 | AC18: 2
A19: 1809 | B19: 劳梓晋 | C19: 647 | D19: 15 | F19: 1808 | G19: 崔子裕 | H19: 146 | I19: 4 | K19: 1801 | L19: 李宗誉 | M19: 100 | N19: 1 | P19: 1818 | Q19: 黄倩茹 | R19: 568.5 | S19: 16 | U19: 1818 | V19: 苏雨昕 | W19: 137 | X19: 3 | Z19: 1818 | AA19: 黎钊阳 | AB19: 90 | AC19: 2
A20: 1810 | B20: 江晓毅 | C20: 646.5 | D20: 17 | F20: 1802 | G20: 黎文垚 | H20: 144 | I20: 5 | K20: 1809 | L20: 潘黄画意 | M20: 100 | N20: 1 | P20: 1818 | Q20: 饶幸怡 | R20: 568 | S20: 17 | U20: 1818 | V20: 欧沛杨 | W20: 126 | X20: 4 | Z20: 1818 | AA20: 钟妙鸣 | AB20: 88 | AC20: 4
A21: 1809 | B21: 陈诗梦 | C21: 646 | D21: 18 | F21: 1811 | G21: 姚舜宇 | H21: 144 | I21: 5 | K21: 1805 | L21: 何俊锐 | M21: 100 | N21: 1 | P21: 1818 | Q21: 曾宪杭 | R21: 568 | S21: 17 | U21: 1818 | V21: 黄颖珊 | W21: 121 | X21: 5 | Z21: 1818 | AA21: 梁成 | AB21: 88 | AC21: 4
A22: 1810 | B22: 韦惠钰 | C22: 645 | D22: 19 | F22: 1813 | G22: 童劲光 | H22: 144 | I22: 5 | K22: 1817 | L22: 梁焜鹏 | M22: 100 | N22: 1 | P22: 1818 | Q22: 周娆涛 | R22: 567.5 | S22: 19 | U22: 1818 | V22: 宾颖淇 | W22: 119 | X22: 6 | Z22: 1818 | AA22: 周娆涛 | AB22: 87 | AC22: 6
A23: 1809 | B23: 陈颖烨 | C23: 644.5 | D23: 20 | F23: 1809 | G23: 黄嘉雨 | H23: 143 | I23: 8 | K23: 1809 | L23: 劳梓晋 | M23: 100 | N23: 1 | P23: 1818 | Q23: 谢依君 | R23: 564 | S23: 20 | U23: 1818 | V23: 李铿锵 | W23: 119 | X23: 6 | Z23: 1818 | AA23: 郭筱婷 | AB23: 86 | AC23: 7
A24: 1809 | B24: 林聪 | C24: 642.5 | D24: 21 | F24: 1809 | G24: 潘黄画意 | H24: 143 | I24: 8 | K24: 1809 | L24: 李茜 | M24: 100 | N24: 1 | P24: 1819 | Q24: 李立珍 | R24: 562.5 | S24: 21 | U24: 1818 | V24: 黎钊阳 | W24: 118 | X24: 8 | Z24: 1818 | AA24: 梁峻豪 | AB24: 85 | AC24: 8
A25: 1803 | B25: 陈柯维 | C25: 642 | D25: 22 | F25: 1810 | G25: 江晓毅 | H25: 143 | I25: 8 | K25: 1810 | L25: 严冬仪 | M25: 100 | N25: 1 | P25: 1818 | Q25: 黄婕妤 | R25: 562 | S25: 22 | U25: 1818 | V25: 李诗洋 | W25: 118 | X25: 8 | Z25: 1818 | AA25: 张伊妍 | AB25: 85 | AC25: 8
A26: 1809 | B26: 何子云 | C26: 641.5 | D26: 23 | K26: 1809 | L26: 于奕星 | M26: 100 | N26: 1 | P26: 1818 | Q26: 邱夏 | R26: 557.5 | S26: 23 | U26: 1818 | V26: 黄子聪 | W26: 118 | X26: 8 | Z26: 1820 | AA26: 莫思淇 | AB26: 85 | AC26: 8
A27: 1809 | B27: 李茜 | C27: 640.5 | D27: 24 | F27: 班级 | G27: 姓名 | H27: 英语 | I27: 排名 | K27: 1816 | L27: 赖伟业 | M27: 100 | N27: 1 | P27: 1818 | Q27: 袁意 | R27: 550.5 | S27: 24
A28: 1809 | B28: 陈湘王莹 | C28: 638 | D28: 25 | F28: 1810 | G28: 韦惠钰 | H28: 141 | I28: 1 | K28: 1813 | L28: 蒙晓桐 | M28: 100 | N28: 1 | P28: 1818 | Q28: 李铿锵 | R28: 549.5 | S28: 25
A29: 1809 | B29: 陈佳强 | C29: 637.5 | D29: 26 | F29: 1812 | G29: 谭砚桁 | H29: 138.5 | I29: 2 | P29: 1818 | Q29: 张伊妍 | R29: 547.5 | S29: 26
A30: 1802 | B30: 方仕锋 | C30: 636.5 | D30: 27 | F30: 1801 | G30: 李宗誉 | H30: 137.5 | I30: 3 | K30: 班级 | L30: 姓名 | M30: 生物 | N30: 排名 | P30: 1820 | Q30: 杨林遐 | R30: 542.5 | S30: 27 | U30: 班级 | V30: 姓名 | W30: 英语 | X30: 排名 | Z30: 班级 | AA30: 姓名 | AB30: 地理 | AC30: 排名
A31: 1809 | B31: 吴聊 | C31: 636 | D31: 28 | F31: 1806 | G31: 梅天傲 | H31: 137.5 | I31: 3 | K31: 1814 | L31: 李坤明 | M31: 88 | N31: 1 | P31: 1818 | Q31: 覃凯琳 | R31: 538.5 | S31: 28 | U31: 1818 | V31: 欧沛杨 | W31: 141 | X31: 1 | Z31: 1820 | AA31: 陈洁 | AB31: 79 | AC31: 1
A32: 1804 | B32: 石恩豪 | C32: 634 | D32: 29 | F32: 1809 | G32: 陈诗梦 | H32: 137 | I32: 5 | K32: 1809 | L32: 林梅兰 | M32: 87 | N32: 2 | P32: 1818 | Q32: 钟玉倩 | R32: 538.5 | S32: 28 | U32: 1818 | V32: 黄麒高 | W32: 139.5 | X32: 2 | Z32: 1818 | AA32: 李诗洋 | AB32: 78 | AC32: 2
A33: 1809 | B33: 徐莆钧 | C33: 634 | D33: 29 | F33: 1804 | G33: 潘思成 | H33: 136 | I33: 6 | K33: 1813 | L33: 黎伊雯 | M33: 87 | N33: 2 | P33: 1818 | Q33: 李勇材 | R33: 534.5 | S33: 30 | U33: 1820 | V33: 欧沛楠 | W33: 134 | X33: 3 | Z33: 1818 | AA33: 钟妙鸣 | AB33: 76 | AC33: 3
A34: 1814 | B34: 李坤明 | C34: 632.5 | D34: 31 | F34: 1816 | G34: 霍宗尧 | H34: 135.5 | I34: 7 | K34: 1802 | L34: 方仕锋 | M34: 87 | N34: 2 | P34: 1818 | Q34: 李思思 | R34: 532.5 | S34: 31 | U34: 1818 | V34: 钟妙鸣 | W34: 133.5 | X34: 4 | Z34: 1818 | AA34: 刘家丽 | AB34: 73 | AC34: 4
A35: 1805 | B35: 黄嘉丽 | C35: 630.5 | D35: 32 | F35: 1809 | G35: 劳梓晋 | H35: 135 | I35: 8 | K35: 1809 | L35: 李泳恩 | M35: 87 | N35: 2 | P35: 1820 | Q35: 莫凯茵 | R35: 532 | S35: 32 | U35: 1818 | V35: 宾颖淇 | W35: 132.5 | X35: 5 | Z35: 1819 | AA35: 李楚莹 | AB35: 72 | AC35: 5
A36: 1809 | B36: 黄耀萱 | C36: 629.5 | D36: 33 | F36: 1815 | G36: 钟榆盛 | H36: 135 | I36: 8 | K36: 1802 | L36: 陈卓斌 | M36: 87 | N36: 2 | P36: 1820 | Q36: 潘佳慧 | R36: 531 | S36: 33 | U36: 1818 | V36: 何希言 | W36: 132.5 | X36: 5 | Z36: 1818 | AA36: 宾颖淇 | AB36: 72 | AC36: 5
A37: 1801 | B37: 陆嘉杰 | C37: 628.5 | D37: 34 | F37: 1817 | G37: 李炳坚 | H37: 134.5 | I37: 10 | K37: 1809 | L37: 陈冠帆 | M37: 86 | N37: 7 | P37: 1819 | Q37: 黄妙乐 | R37: 530.5 | S37: 34 | U37: 1818 | V37: 黄颖珊 | W37: 131.5 | X37: 7 | Z37: 1818 | AA37: 苏雨昕 | AB37: 71 | AC37: 7
A38: 1810 | B38: 陈兆康 | C38: 628.5 | D38: 34 | F38: 1813 | G38: 梁怡菁 | H38: 134.5 | I38: 10 | K38: 1803 | L38: 陈柯维 | M38: 86 | N38: 7 | P38: 1818 | Q38: 陈扬 | R38: 530 | S38: 35 | U38: 1820 | V38: 吴虹漫 | W38: 131.5 | X38: 7 | Z38: 1818 | AA38: 黎钊阳 | AB38: 71 | AC38: 7
A39: 1809 | B39: 梁嘉辉 | C39: 628 | D39: 36 | K39: 1808 | L39: 胡永华 | M39: 86 | N39: 7 | P39: 1818 | Q39: 梁耀文 | R39: 529.5 | S39: 36 | U39: 1818 | V39: 苏雨昕 | W39: 129.5 | X39: 9 | Z39: 1818 | AA39: 黄颖珊 | AB39: 70 | AC39: 9
A40: 1809 | B40: 于奕星 | C40: 627.5 | D40: 37 | K40: 1801 | L40: 谢链飞 | M40: 86 | N40: 7 | P40: 1819 | Q40: 唐楚艺 | R40: 529.5 | S40: 36 | U40: 1818 | V40: 许心愿 | W40: 129.5 | X40: 9 | Z40: 1819 | AA40: 李立珍 | AB40: 70 | AC40: 9
...

Sheet 机改成绩
A1: 学生成绩理科 | AB1: 学生成绩文科
A2: 学号 | B2: 考号 | C2: 姓名 | D2: 文理类型 | E2: 班级 | F2: 语文 | I2: 数学 | L2: 英语 | O2: 物理 | R2: 化学 | U2: 生物 | X2: 总分 | AB2: 学号 | AC2: 考号 | AD2: 姓名 | AE2: 文理类型 | AF2: 班级 | AG2: 语文 | AJ2: 数学 | AM2: 英语 | AP2: 政治 | AS2: 历史 | AV2: 地理 | AY2: 总分
F3: 分数 | G3: 班名 | H3: 级名 | I3: 分数 | J3: 班名 | K3: 级名 | L3: 分数 | M3: 班名 | N3: 级名 | O3: 分数 | P3: 班名 | Q3: 级名 | R3: 分数 | S3: 班名 | T3: 级名 | U3: 分数 | V3: 班名 | W3: 级名 | X3: 分数 | Y3: 班名 | Z3: 级名 | AG3: 分数 | AH3: 班名 | AI3: 级名 | AJ3: 分数 | AK3: 班名 | AL3: 级名 | AM3: 分数 | AN3: 班名 | AO3: 级名 | AP3: 分数 | AQ3: 班名 | AR3: 级名 | AS3: 分数 | AT3: 班名 | AU3: 级名 | AV3: 分数 | AW3: 班名 | AX3: 级名 | AY3: 分数 | AZ3: 班名 | BA3: 级名
A4: 181413 | B4: 181413 | C4: 范馨尹 | D4: 理科 | E4: 1814 | F4: 128 | G4: 1 | H4: 3 | I4: 142 | J4: 1 | K4: 10 | L4: 133.5 | M4: 1 | N4: 13 | O4: 93 | P4: 1 | Q4: 39 | R4: 92 | S4: 4 | T4: 116 | U4: 83 | V4: 2 | W4: 30 | X4: 671.5 | Y4: 1 | Z4: 1 | AB4: 181851 | AC4: 181851 | AD4: 钟妙鸣 | AE4: 文科 | AF4: 1818 | AG4: 126 | AH4: 2 | AI4: 2 | AJ4: 142 | AK4: 2 | AL4: 2 | AM4: 133.5 | AN4: 3 | AO4: 4 | AP4: 88 | AQ4: 4 | AR4: 4 | AS4: 88 | AT4: 4 | AU4: 4 | AV4: 76 | AW4: 2 | AX4: 3 | AY4: 653.5 | AZ4: 1 | BA4: 1
A5: 180934 | B5: 180934 | C5: 潘黄画意 | D5: 理科 | E5: 1809 | F5: 121 | G5: 10 | H5: 30 | I5: 143 | J5: 1 | K5: 7 | L5: 127.5 | M5: 22 | N5: 63 | O5: 95 | P5: 10 | Q5: 31 | R5: 100 | S5: 1 | T5: 1 | U5: 84 | V5: 8 | W5: 21 | X5: 670.5 | Y5: 1 | Z5: 2 | AB5: 181836 | AC5: 181836 | AD5: 欧沛杨 | AE5: 文科 | AF5: 1818 | AG5: 119 | AH5: 14 | AI5: 21 | AJ5: 126 | AK5: 4 | AL5: 4 | AM5: 141 | AN5: 1 | AO5: 1 | AP5: 98 | AQ5: 1 | AR5: 1 | AS5: 90 | AT5: 2 | AU5: 2 | AV5: 67 | AW5: 9 | AX5: 12 | AY5: 641 | AZ5: 2 | BA5: 2
A6: 180912 | B6: 180912 | C6: 黄嘉雨 | D6: 理科 | E6: 1809 | F6: 117 | G6: 21 | H6: 86 | I6: 143 | J6: 1 | K6: 7 | L6: 127 | M6: 23 | N6: 72 | O6: 103 | P6: 4 | Q6: 7 | R6: 100 | S6: 1 | T6: 1 | U6: 80 | V6: 19 | W6: 85 | X6: 670 | Y6: 2 | Z6: 3 | AB6: 181842 | AC6: 181842 | AD6: 苏雨昕 | AE6: 文科 | AF6: 1818 | AG6: 117 | AH6: 19 | AI6: 27 | AJ6: 137 | AK6: 3 | AL6: 3 | AM6: 129.5 | AN6: 7 | AO6: 9 | AP6: 87 | AQ6: 6 | AR6: 6 | AS6: 96 | AT6: 1 | AU6: 1 | AV6: 71 | AW6: 5 | AX6: 7 | AY6: 637.5 | AZ6: 3 | BA6: 3
A7: 180129 | B7: 180129 | C7: 李宗誉 | D7: 理科 | E7: 1801 | F7: 110 | G7: 10 | H7: 310 | I7: 140 | J7: 2 | K7: 15 | L7: 137.5 | M7: 1 | N7: 3 | O7: 98 | P7: 2 | Q7: 18 | R7: 100 | S7: 1 | T7: 1 | U7: 82 | V7: 4 | W7: 46 | X7: 667.5 | Y7: 1 | Z7: 4 | AB7: 181817 | AC7: 181817 | AD7: 黄颖珊 | AE7: 文科 | AF7: 1818 | AG7: 129 | AH7: 1 | AI7: 1 | AJ7: 121 | AK7: 5 | AL7: 5 | AM7: 131.5 | AN7: 6 | AO7: 7 | AP7: 83 | AQ7: 14 | AR7: 16 | AS7: 81 | AT7: 18 | AU7: 22 | AV7: 70 | AW7: 7 | AX7: 9 | AY7: 615.5 | AZ7: 4 | BA7: 4
A8: 180950 | B8: 180950 | C8: 邹禹盈 | D8: 理科 | E8: 1809 | F8: 119 | G8: 15 | H8: 51 | I8: 131 | J8: 11 | K8: 48 | L8: 128.5 | M8: 19 | N8: 53 | O8: 106 | P8: 1 | Q8: 1 | R8: 96 | S8: 23 | T8: 45 | U8: 84 | V8: 8 | W8: 21 | X8: 664.5 | Y8: 3 | Z8: 5 | AB8: 181831 | AC8: 181831 | AD8: 刘家丽 | AE8: 文科 | AF8: 1818 | AG8: 114 | AH8: 29 | AI8: 44 | AJ8: 143 | AK8: 1 | AL8: 1 | AM8: 118 | AN8: 33 | AO8: 49 | AP8: 90 | AQ8: 2 | AR8: 2 | AS8: 77 | AT8: 30 | AU8: 48 | AV8: 73 | AW8: 3 | AX8: 4 | AY8: 615 | AZ8: 5 | BA8: 5
A9: 180215 | B9: 180215 | C9: 黎文垚 | D9: 理科 | E9: 1802 | F9: 110 | G9: 19 | H9: 310 | I9: 144 | J9: 1 | K9: 4 | L9: 127.5 | M9: 4 | N9: 63 | O9: 105 | P9: 1 | Q9: 2 | R9: 99 | S9: 1 | T9: 13 | U9: 78 | V9: 13 | W9: 133 | X9: 663.5 | Y9: 1 | Z9: 6 | AB9: 181822 | AC9: 181822 | AD9: 黎钊阳 | AE9: 文科 | AF9: 1818 | AG9: 123 | AH9: 4 | AI9: 5 | AJ9: 118 | AK9: 8 | AL9: 8 | AM9: 129 | AN9: 9 | AO9: 12 | AP9: 79 | AQ9: 25 | AR9: 35 | AS9: 90 | AT9: 2 | AU9: 2 | AV9: 71 | AW9: 5 | AX9: 7 | AY9: 610 | AZ9: 6 | BA9: 6
A10: 180902 | B10: 180902 | C10: 陈冠帆 | D10: 理科 | E10: 1809 | F10: 121 | G10: 10 | H10: 30 | I10: 137 | J10: 6 | K10: 27 | L10: 130 | M10: 10 | N10: 34 | O10: 91 | P10: 18 | Q10: 56 | R10: 98 | S10: 10 | T10: 20 | U10: 86 | V10: 3 | W10: 7 | X10: 663 | Y10: 4 | Z10: 7 | AB10: 182003 | AC10: 182003 | AD10: 陈洁 | AE10: 文科 | AF10: 1820 | AG10: 121 | AH10: 3 | AI10: 8 | AJ10: 112 | AK10: 1 | AL10: 14 | AM10: 125 | AN10: 5 | AO10: 31 | AP10: 78 | AQ10: 11 | AR10: 46 | AS10: 84 | AT10: 2 | AU10: 11 | AV10: 79 | AW10: 1 | AX10: 1 | AY10: 599 | AZ10: 1 | BA10: 7
A11: 180916 | B11: 180916 | C11: 纪奔妤 | D11: 理科 | E11: 1809 | F11: 122 | G11: 8 | H11: 25 | I11: 140 | J11: 3 | K11: 15 | L11: 130 | M11: 10 | N11: 34 | O11: 93 | P11: 12 | Q11: 39 | R11: 96 | S11: 23 | T11: 45 | U11: 77 | V11: 27 | W11: 162 | X11: 658 | Y11: 5 | Z11: 8 | AB11: 181801 | AC11: 181801 | AD11: 宾颖淇 | AE11: 文科 | AF11: 1818 | AG11: 110 | AH11: 39 | AI11: 68 | AJ11: 119 | AK11: 6 | AL11: 6 | AM11: 132.5 | AN11: 4 | AO11: 5 | AP11: 86 | AQ11: 8 | AR11: 9 | AS11: 79 | AT11: 25 | AU11: 35 | AV11: 72 | AW11: 4 | AX11: 5 | AY11: 598.5 | AZ11: 7 | BA11: 8
A12: 180935 | B12: 180935 | C12: 潘铭真 | D12: 理科 | E12: 1809 | F12: 125 | G12: 4 | H12: 12 | I12: 127 | J12: 20 | K12: 78 | L12: 133 | M12: 4 | N12: 17 | O12: 96 | P12: 8 | Q12: 25 | R12: 96 | S12: 23 | T12: 45 | U12: 79 | V12: 20 | W12: 103 | X12: 656 | Y12: 6 | Z12: 9 | AB12: 181847 | AC12: 181847 | AD12: 许心愿 | AE12: 文科 | AF12: 1818 | AG12: 117 | AH12: 19 | AI12: 27 | AJ12: 117 | AK12: 11 | AL12: 11 | AM12: 129.5 | AN12: 7 | AO12: 9 | AP12: 83 | AQ12: 14 | AR12: 16 | AS12: 83 | AT12: 11 | AU12: 13 | AV12: 66 | AW12: 10 | AX12: 13 | AY12: 595.5 | AZ12: 8 | BA12: 9
A13: 180510 | B13: 180510 | C13: 何俊锐 | D13: 理科 | E13: 1805 | F13: 114 | G13: 12 | H13: 170 | I13: 139 | J13: 1 | K13: 21 | L13: 125 | M13: 4 | N13: 96 | O13: 93 | P13: 3 | Q13: 39 | R13: 100 | S13: 1 | T13: 1 | U13: 85 | V13: 1 | W13: 14 | X13: 656 | Y13: 1 | Z13: 9 | AB13: 181811 | AC13: 181811 | AD13: 何希言 | AE13: 文科 | AF13: 1818 | AG13: 115 | AH13: 25 | AI13: 38 | AJ13: 110 | AK13: 14 | AL13: 16 | AM13: 132.5 | AN13: 4 | AO13: 5 | AP13: 84 | AQ13: 10 | AR13: 12 | AS13: 84 | AT13: 10 | AU13: 11 | AV13: 66 | AW13: 10 | AX13: 13 | AY13: 591.5 | AZ13: 9 | BA13: 10
A14: 180930 | B14: 180930 | C14: 刘志锋 | D14: 理科 | E14: 1809 | F14: 119 | G14: 15 | H14: 51 | I14: 130 | J14: 13 | K14: 54 | L14: 132 | M14: 6 | N14: 22 | O14: 92 | P14: 16 | Q14: 48 | R14: 98 | S14: 10 | T14: 20 | U14: 81 | V14: 13 | W14: 66 | X14: 652 | Y14: 7 | Z14: 11 | AB14: 181815 | AC14: 181815 | AD14: 黄麒高 | AE14: 文科 | AF14: 1818 | AG14: 116 | AH14: 23 | AI14: 32 | AJ14: 98 | AK14: 21 | AL14: 26 | AM14: 139.5 | AN14: 2 | AO14: 2 | AP14: 84 | AQ14: 10 | AR14: 12 | AS14: 83 | AT14: 11 | AU14: 13 | AV14: 58 | AW14: 22 | AX14: 33 | AY14: 578.5 | AZ14: 10 | BA14: 11
A15: 181348 | B15: 181348 | C15: 童劲光 | D15: 理科 | E15: 1813 | F15: 112 | G15: 13 | H15: 226 | I15: 144 | J15: 1 | K15: 4 | L15: 126 | M15: 7 | N15: 82 | O15: 93 | P15: 1 | Q15: 39 | R15: 92 | S15: 5 | T15: 116 | U15: 83 | V15: 2 | W15: 30 | X15: 650 | Y15: 1 | Z15: 12 | AB15: 181823 | AC15: 181823 | AD15: 李佳茵 | AE15: 文科 | AF15: 1818 | AG15: 124 | AH15: 3 | AI15: 4 | AJ15: 111 | AK15: 13 | AL15: 15 | AM15: 125.5 | AN15: 20 | AO15: 27 | AP15: 83 | AQ15: 14 | AR15: 16 | AS15: 77 | AT15: 30 | AU15: 48 | AV15: 56 | AW15: 31 | AX15: 43 | AY15: 576.5 | AZ15: 11 | BA15: 12
... A123: 181042 | B123: 181042 | C123: 吴海梅 | D123: 理科 | E123: 1810 | F123: 110 | G123: 31 | H123: 310 | I123: 106 | J123: 26 | K123: 322 | L123: 120 | M123: 19 | N123: 211 | O123: 85 | P123: 11 | Q123: 117 | R123: 97 | S123: 3 | T123: 30 | U123: 77 | V123: 12 | W123: 162 | X123: 595 | Y123: 14 | Z123: 120 | AB123: 181906 | AC123: 181906 | AD123: 贺细晴 | AE123: 文科 | AF123: 1819 | AG123: 92 | AH123: 33 | AI123: 118 | AJ123: 42 | AK123: 29 | AL123: 111 | AM123: 107.5 | AN123: 12 | AO123: 76 | AP123: 61 | AQ123: 33 | AR123: 116 | AS123: 52 | AT123: 34 | AU123: 119 | AV123: 45 | AW123: 23 | AX123: 96 | AY123: 399.5 | AZ123: 34 | BA123: 120
A124: 181112 | B124: 181112 | C124: 黄光铧 | D124: 理科 | E124: 1811 | F124: 107 | G124: 21 | H124: 429 | I124: 126 | J124: 4 | K124: 86 | L124: 115 | M124: 16 | N124: 330 | O124: 85 | P124: 6 | Q124: 117 | R124: 83 | S124: 21 | T124: 407 | U124: 79 | V124: 7 | W124: 103 | X124: 595 | Y124: 6 | Z124: 120
A125: 180921 | B125: 180921 | C125: 李舒婷 | D125: 理科 | E125: 1809 | F125: 113 | G125: 32 | H125: 196 | I125: 114 | J125: 37 | K125: 215 | L125: 112.5 | M125: 49 | N125: 401 | O125: 96 | P125: 8 | Q125: 25 | R125: 91 | S125: 38 | T125: 151 | U125: 68 | V125: 42 | W125: 452 | X125: 594.5 | Y125: 37 | Z125: 122
A126: 180742 | B126: 180742 | C126: 唐荣霞 | D126: 理科 | E126: 1807 | F126: 118 | G126: 5 | H126: 69 | I126: 102 | J126: 20 | K126: 386 | L126: 119 | M126: 10 | N126: 237 | O126: 85 | P126: 9 | Q126: 117 | R126: 91 | S126: 5 | T126: 151 | U126: 79 | V126: 2 | W126: 103 | X126: 594 | Y126: 6 | Z126: 123
A127: 180802 | B127: 180802 | C127: 陈泓策 | D127: 理科 | E127: 1808 | F127: 115 | G127: 7 | H127: 140 | I127: 108 | J127: 13 | K127: 296 | L127: 116 | M127: 14 | N127: 309 | O127: 82 | P127: 10 | Q127: 171 | R127: 90 | S127: 7 | T127: 177 | U127: 83 | V127: 4 | W127: 30 | X127: 594 | Y127: 5 | Z127: 123
A128: 180419 | B128: 180419 | C128: 黎桂玫 | D128: 理科 | E128: 1804 | F128: 105 | G128: 20 | H128: 515 | I128: 140 | J128: 1 | K128: 15 | L128: 103 | M128: 38 | N128: 630 | O128: 80 | P128: 5 | Q128: 211 | R128: 87 | S128: 17 | T128: 268 | U128: 79 | V128: 10 | W128: 103 | X128: 594 | Y128: 4 | Z128: 123
A129: 180516 | B129: 180516 | C129: 黄思帆 | D129: 理科 | E129: 1805 | F129: 111 | G129: 21 | H129: 271 | I129: 115 | J129: 8 | K129: 195 | L129: 118 | M129: 17 | N129: 263 | O129: 85 | P129: 7 | Q129: 117 | R129: 93 | S129: 3 | T129: 93 | U129: 71 | V129: 12 | W129: 342 | X129: 593 | Y129: 5 | Z129: 126
A130: 180339 | B130: 180339 | C130: 盘盈 | D130: 理科 | E130: 1803 | F130: 117 | G130: 5 | H130: 86 | I130: 130 | J130: 3 | K130: 54 | L130: 107.5 | M130: 31 | N130: 532 | O130: 83 | P130: 13 | Q130: 153 | R130: 75 | S130: 49 | T130: 671 | U130: 80 | V130: 10 | W130: 85 | X130: 592.5 | Y130: 9 | Z130: 127
A131: 180546 | B131: 180546 | C131: 谭至昕 | D131: 理科 | E131: 1805 | F131: 119 | G131: 4 | H131: 51 | I131: 117 | J131: 7 | K131: 174 | L131: 123 | M131: 8 | N131: 132 | O131: 87 | P131: 4 | Q131: 92 | R131: 75 | S131: 34 | T131: 671 | U131: 71 | V131: 12 | W131: 342 | X131: 592 | Y131: 6 | Z131: 128
A132: 180755 | B132: 180755 | C132: 钟雪晴 | D132: 理科 | E132: 1807 | F132: 107 | G132: 23 | H132: 429 | I132: 122 | J132: 5 | K132: 116 | L132: 105 | M132: 28 | N132: 578 | O132: 90 | P132: 1 | Q132: 63 | R132: 93 | S132: 3 | T132: 93 | U132: 75 | V132: 9 | W132: 219 | X132: 592 | Y132: 7 | Z132: 128
A133: 181252 | B133: 181252 | C133: 严弋孜 | D133: 理科 | E133: 1812 | F133: 119 | G133: 2 | H133: 51 | I133: 111 | J133: 16 | K133: 247 | L133: 120 | M133: 10 | N133: 211 | O133: 78 | P133: 15 | Q133: 256 | R133: 89 | S133: 7 | T133: 200 | U133: 75 | V133: 10 | W133: 219 | X133: 592 | Y133: 6 | Z133: 128
A134: 181718 | B134: 181718 | C134: 柯璐璐 | D134: 理科 | E134: 1817 | F134: 114 | G134: 13 | H134: 170 | I134: 115 | J134: 10 | K134: 195 | L134: 118 | M134: 13 | N134: 263 | O134: 71 | P134: 25 | Q134: 411 | R134: 92 | S134: 8 | T134: 116 | U134: 82 | V134: 2 | W134: 46 | X134: 592 | Y134: 7 | Z134: 128
A135: 180751 | B135: 180751 | C135: 钟德植 | D135: 理科 | E135: 1807 | F135: 115 | G135: 10 | H135: 140 | I135: 111 | J135: 11 | K135: 247 | L135: 120.5 | M135: 5 | N135: 192 | O135: 89 | P135: 4 | Q135: 79 | R135: 83 | S135: 17 | T135: 407 | U135: 73 | V135: 13 | W135: 275 | X135: 591.5 | Y135: 8 | Z135: 132
... A828: 180141 | B828: 180141 | C828: 马浩莹 | D828: 理科 | E828: 1801 | F828: 102 | G828: 30 | H828: 655 | I828: 72 | J828: 49 | K828: 802 | L828: 88 | M828: 48 | N828: 852 | O828: 55 | P828: 45 | Q828: 748 | R828: 74 | S828: 46 | T828: 702 | U828: 66 | V828: 36 | W828: 519 | X828: 457 | Y828: 48 | Z828: 825
A829: 181236 | B829: 181236 | C829: 莫棋 | D829: 理科 | E829: 1812 | F829: 112 | G829: 12 | H829: 226 | L829: 114.5 | M829: 18 | N829: 340 | O829: 80 | P829: 11 | Q829: 211 | R829: 86 | S829: 12 | T829: 304 | U829: 63 | V829: 36 | W829: 625 | X829: 455.5 | Y829: 46 | Z829: 826
A830: 180237 | B830: 180237 | C830: 聂铭君 | D830: 理科 | E830: 1802 | F830: 84 | G830: 57 | H830: 933 | I830: 105 | J830: 20 | K830: 340 | L830: 103 | M830: 35 | N830: 630 | O830: 34 | P830: 55 | Q830: 933 | R830: 64 | S830: 55 | T830: 881 | U830: 65 | V830: 38 | W830: 554 | X830: 455 | Y830: 48 | Z830: 827
A831: 181102 | B831: 181102 | C831: 陈承昌 | D831: 理科 | E831: 1811 | F831: 91 | G831: 54 | H831: 890 | I831: 84 | J831: 38 | K831: 658 | L831: 114 | M831: 19 | N831: 356 | O831: 40 | P831: 56 | Q831: 909 | R831: 67 | S831: 49 | T831: 837 | U831: 59 | V831: 49 | W831: 729 | X831: 455 | Y831: 52 | Z831: 827
A832: 180801 | B832: 180801 | C832: 曾婷慧 | D832: 理科 | E832: 1808 | F832: 94 | G832: 52 | H832: 856 | I832: 58 | J832: 55 | K832: 893 | L832: 110.5 | M832: 22 | N832: 465 | O832: 53 | P832: 47 | Q832: 786 | R832: 73 | S832: 39 | T832: 717 | U832: 66 | V832: 37 | W832: 519 | X832: 454.5 | Y832: 49 | Z832: 829
A833: 180212 | B833: 180212 | C833: 黄颖茵 | D833: 理科 | E833: 1802 | F833: 114 | G833: 8 | H833: 170 | I833: 75 | J833: 45 | K833: 766 | L833: 92.5 | M833: 47 | N833: 801 | O833: 49 | P833: 48 | Q833: 842 | R833: 73 | S833: 42 | T833: 717 | U833: 51 | V833: 55 | W833: 862 | X833: 454.5 | Y833: 49 | Z833: 829
A834: 180119 | B834: 180119 | C834: 黄昕玥 | D834: 理科 | E834: 1801 | F834: 99 | G834: 40 | H834: 754 | I834: 80 | J834: 42 | K834: 699 | L834: 100.5 | M834: 34 | N834: 675 | O834: 56 | P834: 43 | Q834: 731 | R834: 85 | S834: 17 | T834: 339 | U834: 34 | V834: 57 | W834: 946 | X834: 454.5 | Y834: 49 | Z834: 829
A835: 180242 | B835: 180242 | C835: 覃金慧 | D835: 理科 | E835: 1802 | F835: 103 | G835: 39 | H835: 606 | I835: 57 | J835: 54 | K835: 902 | L835: 85 | M835: 51 | N835: 870 | O835: 47 | P835: 49 | Q835: 863 | R835: 87 | S835: 14 | T835: 268 | U835: 75 | V835: 18 | W835: 219 | X835: 454 | Y835: 50 | Z835: 832
A836: 180314 | B836: 180314 | C836: 黄於情 | D836: 理科 | E836: 1803 | F836: 92 | G836: 53 | H836: 882 | I836: 109 | J836: 18 | K836: 278 | L836: 88.5 | M836: 50 | N836: 848 | O836: 33 | P836: 57 | Q836: 936 | R836: 81 | S836: 34 | T836: 474 | U836: 50 | V836: 55 | W836: 873 | X836: 453.5 | Y836: 52 | Z836: 833
A837: 181749 | B837: 181749 | C837: 卫楚雯 | D837: 理科 | E837: 1817 | F837: 98 | G837: 47 | H837: 774 | I837: 70 | J837: 45 | K837: 815 | L837: 110.5 | M837: 26 | N837: 465 | O837: 47 | P837: 54 | Q837: 863 | R837: 61 | S837: 53 | T837: 901 | U837: 67 | V837: 25 | W837: 489 | X837: 453.5 | Y837: 47 | Z837: 833
A838: 181316 | B838: 181316 | C838: 黄昌泉 | D838: 理科 | E838: 1813 | F838: 96 | G838: 48 | H838: 814 | I838: 70 | J838: 43 | K838: 815 | L838: 100 | M838: 41 | N838: 680 | O838: 57 | P838: 39 | Q838: 713 | R838: 68 | S838: 46 | T838: 824 | U838: 62 | V838: 33 | W838: 657 | X838: 453 | Y838: 45 | Z838: 835
A839: 181435 | B839: 181435 | C839: 龙家银 | D839: 理科 | E839: 1814 | F839: 84 | G839: 55 | H839: 933 | I839: 75 | J839: 46 | K839: 766 | L839: 102 | M839: 43 | N839: 642 | O839: 60 | P839: 41 | Q839: 647 | R839: 64 | S839: 53 | T839: 881 | U839: 68 | V839: 29 | W839: 452 | X839: 453 | Y839: 50 | Z839: 835
...

Sheet 理科
A1: 考号 | B1: 班级 | C1: 姓名 | D1: 语文 | E1: 语文单排 | F1: 数学 | G1: 数学单排 | H1: 英语 | I1: 英语单排 | J1: 物理 | K1: 物理单排 | L1: 化学 | M1: 化学单排 | N1: 生物 | O1: 生物单排 | P1: 月考总分 | Q1: 班级排名 | R1: 年级排名
A2: 181413 | B2: 1814 | C2: 范馨尹 | D2: 128 | E2: 3 | F2: 142 | G2: 11 | H2: 133.5 | I2: 13 | J2: 93 | K2: 39 | L2: 92 | M2: 116 | N2: 83 | O2: 30 | P2: 671.5 | Q2: 1 | R2: 1
A3: 180934 | B3: 1809 | C3: 潘黄画意 | D3: 121 | E3: 30 | F3: 143 | G3: 8 | H3: 127.5 | I3: 63 | J3: 95 | K3: 31 | L3: 100 | M3: 1 | N3: 84 | O3: 21 | P3: 670.5 | Q3: 1 | R3: 2
A4: 180912 | B4: 1809 | C4: 黄嘉雨 | D4: 117 | E4: 86 | F4: 143 | G4: 8 | H4: 127 | I4: 72 | J4: 103 | K4: 7 | L4: 100 | M4: 1 | N4: 80 | O4: 85 | P4: 670 | Q4: 2 | R4: 3
A5: 180129 | B5: 1801 | C5: 李宗誉 | D5: 110 | E5: 310 | F5: 140 | G5: 16 | H5: 137.5 | I5: 3 | J5: 98 | K5: 18 | L5: 100 | M5: 1 | N5: 82 | O5: 46 | P5: 667.5 | Q5: 1 | R5: 4
A6: 180950 | B6: 1809 | C6: 邹禹盈 | D6: 119 | E6: 51 | F6: 131 | G6: 48 | H6: 128.5 | I6: 53 | J6: 106 | K6: 1 | L6: 96 | M6: 45 | N6: 84 | O6: 21 | P6: 664.5 | Q6: 3 | R6: 5
A7: 180215 | B7: 1802 | C7: 黎文垚 | D7: 110 | E7: 310 | F7: 144 | G7: 5 | H7: 127.5 | I7: 63 | J7: 105 | K7: 2 | L7: 99 | M7: 13 | N7: 78 | O7: 133 | P7: 663.5 | Q7: 1 | R7: 6
A8: 180902 | B8: 1809 | C8: 陈冠帆 | D8: 121 | E8: 30 | F8: 137 | G8: 28 | H8: 130 | I8: 34 | J8: 91 | K8: 56 | L8: 98 | M8: 20 | N8: 86 | O8: 7 | P8: 663 | Q8: 4 | R8: 7
A9: 180916 | B9: 1809 | C9: 纪奔妤 | D9: 122 | E9: 25 | F9: 140 | G9: 16 | H9: 130 | I9: 34 | J9: 93 | K9: 39 | L9: 96 | M9: 45 | N9: 77 | O9: 162 | P9: 658 | Q9: 5 | R9: 8
A10: 180923 | B10: 1809 | C10: 梁安然 | D10: 99 | E10: 754 | F10: 148 | G10: 1 | H10: 125.5 | I10: 87 | J10: 104 | K10: 3 | L10: 100 | M10: 1 | N10: 81 | O10: 66 | P10: 657.5 | Q10: 6 | R10: 9
A11: 180510 | B11: 1805 | C11: 何俊锐 | D11: 114 | E11: 170 | F11: 139 | G11: 22 | H11: 125 | I11: 96 | J11: 93 | K11: 39 | L11: 100 | M11: 1 | N11: 85 | O11: 14 | P11: 656 | Q11: 1 | R11: 10
A12: 180935 | B12: 1809 | C12: 潘铭真 | D12: 125 | E12: 12 | F12: 127 | G12: 78 | H12: 133 | I12: 17 | J12: 96 | K12: 25 | L12: 96 | M12: 45 | N12: 79 | O12: 103 | P12: 656 | Q12: 7 | R12: 10
A13: 180930 | B13: 1809 | C13: 刘志锋 | D13: 119 | E13: 51 | F13: 130 | G13: 54 | H13: 132 | I13: 22 | J13: 92 | K13: 48 | L13: 98 | M13: 20 | N13: 81 | O13: 66 | P13: 652 | Q13: 8 | R13: 12
... A952: 181757 | B952: 1817 | C952: 王嘉宇 | D952: 97 | E952: 795 | F952: 15 | G952: 951 | H952: 35 | I952: 951 | J952: 26 | K952: 947 | L952: 21 | M952: 951 | N952: 33 | O952: 949 | P952: 227 | Q952: 57 | R952: 951

Sheet 文科
A1: 考号 | B1: 班级 | C1: 姓名 | D1: 语文 | E1: 级名 | F1: 数学 | G1: 级名 | H1: 英语 | I1: 级名 | J1: 政治 | K1: 级名 | L1: 历史 | M1: 级名 | N1: 地理 | O1: 级名 | P1: 总分 | Q1: 班名 | R1: 级名
A2: 181851 | B2: 1818 | C2: 钟妙鸣 | D2: 126 | E2: 2 | F2: 142 | G2: 2 | H2: 133.5 | I2: 4 | J2: 88 | K2: 4 | L2: 88 | M2: 4 | N2: 76 | O2: 3 | P2: 653.5 | Q2: 1 | R2: 1
A3: 181836 | B3: 1818 | C3: 欧沛杨 | D3: 119 | E3: 21 | F3: 126 | G3: 4 | H3: 141 | I3: 1 | J3: 98 | K3: 1 | L3: 90 | M3: 2 | N3: 67 | O3: 12 | P3: 641 | Q3: 2 | R3: 2
A4: 181842 | B4: 1818 | C4: 苏雨昕 | D4: 117 | E4: 27 | F4: 137 | G4: 3 | H4: 129.5 | I4: 9 | J4: 87 | K4: 6 | L4: 96 | M4: 1 | N4: 71 | O4: 7 | P4: 637.5 | Q4: 3 | R4: 3
A5: 181817 | B5: 1818 | C5: 黄颖珊 | D5: 129 | E5: 1 | F5: 121 | G5: 5 | H5: 131.5 | I5: 7 | J5: 83 | K5: 16 | L5: 81 | M5: 22 | N5: 70 | O5: 9 | P5: 615.5 | Q5: 4 | R5: 4
A6: 181831 | B6: 1818 | C6: 刘家丽 | D6: 114 | E6: 44 | F6: 143 | G6: 1 | H6: 118 | I6: 49 | J6: 90 | K6: 2 | L6: 77 | M6: 48 | N6: 73 | O6: 4 | P6: 615 | Q6: 5 | R6: 5
A7: 181822 | B7: 1818 | C7: 黎钊阳 | D7: 123 | E7: 5 | F7: 118 | G7: 8 | H7: 129 | I7: 12 | J7: 79 | K7: 35 | L7: 90 | M7: 2 | N7: 71 | O7: 7 | P7: 610 | Q7: 6 | R7: 6
A8: 182003 | B8: 1820 | C8: 陈洁 | D8: 121 | E8: 8 | F8: 112 | G8: 14 | H8: 125 | I8: 31 | J8: 78 | K8: 46 | L8: 84 | M8: 11 | N8: 79 | O8: 1 | P8: 599 | Q8: 1 | R8: 7
A9: 181801 | B9: 1818 | C9: 宾颖淇 | D9: 110 | E9: 68 | F9: 119 | G9: 6 | H9: 132.5 | I9: 5 | J9: 86 | K9: 9 | L9: 79 | M9: 35 | N9: 72 | O9: 5 | P9: 598.5 | Q9: 7 | R9: 8
A10: 181847 | B10: 1818 | C10: 许心愿 | D10: 117 | E10: 27 | F10: 117 | G10: 11 | H10: 129.5 | I10: 9 | J10: 83 | K10: 16 | L10: 83 | M10: 13 | N10: 66 | O10: 13 | P10: 595.5 | Q10: 8 | R10: 9
A11: 181811 | B11: 1818 | C11: 何希言 | D11: 115 | E11: 38 | F11: 110 | G11: 16 | H11: 132.5 | I11: 5 | J11: 84 | K11: 12 | L11: 84 | M11: 11 | N11: 66 | O11: 13 | P11: 591.5 | Q11: 9 | R11: 10
A12: 181815 | B12: 1818 | C12: 黄麒高 | D12: 116 | E12: 32 | F12: 98 | G12: 26 | H12: 139.5 | I12: 2 | J12: 84 | K12: 12 | L12: 83 | M12: 13 | N12: 58 | O12: 33 | P12: 578.5 | Q12: 10 | R12: 11
A13: 181823 | B13: 1818 | C13: 李佳茵 | D13: 124 | E13: 4 | F13: 111 | G13: 15 | H13: 125.5 | I13: 27 | J13: 83 | K13: 16 | L13: 77 | M13: 48 | N13: 56 | O13: 43 | P13: 576.5 | Q13: 11 | R13: 12
... A121: 181906 | B121: 1819 | C121: 贺细晴 | D121: 92 | E121: 118 | F121: 42 | G121: 111 | H121: 107.5 | I121: 76 | J121: 61 | K121: 116 | L121: 52 | M121: 119 | N121: 45 | O121: 96 | P121: 399.5 | Q121: 34 | R121: 120

Sheet 总表
A1: 高一年级1801-1820班月考（1）成绩表 20181017
A2: 学生账号 | B2: 班级 | C2: 考号 | D2: 姓名 | E2: 语文 | F2: 数学 | G2: 英语 | H2: 物理/政治 | I2: 化学/历史 | J2: 生物/地理 | K2: 月考总分 | L2: 班级排名 | M2: 年级排名 | N2: 总成绩 | O2: 学生类别
A3: 20180499 | B3: 1801 | C3: 180101 | D3: 陈程慧 | E3: 87 | F3: 80 | G3: 96.5 | H3: 39 | I3: 70 | J3: 44 | K3: =SUM(E3:J3) -> 416.5 | L3: =RANK(K3,$K$3:$K$59) -> 54 | M3: =RANK(K3,$K$3:$K$953) -> 916 | O3: 市区外公费
A4: 20180117 | B4: 1801 | C4: 180102 | D4: 陈驰宇 | E4: 110 | F4: 131 | G4: 99 | H4: 100 | I4: 94 | J4: 79 | K4: =SUM(E4:J4) -> 613 | L4: =RANK(K4,$K$3:$K$59) -> 3 | M4: =RANK(K4,$K$3:$K$953) -> 64 | N4: A+ | O4: 计划生
A5: 20180593 | B5: 1801 | C5: 180103 | D5: 陈冠林 | E5: 106 | F5: 130 | G5: 113.5 | H5: 75 | I5: 79 | J5: 77 | K5: =SUM(E5:J5) -> 580.5 | L5: =RANK(K5,$K$3:$K$59) -> 4 | M5: =RANK(K5,$K$3:$K$953) -> 176 | N5: A | O5: 市区统招生
A6: 20180898 | B6: 1801 | C6: 180104 | D6: 陈军瑜 | E6: 91 | F6: 82 | G6: 120.5 | H6: 70 | I6: 93 | J6: 61 | K6: =SUM(E6:J6) -> 517.5 | L6: =RANK(K6,$K$3:$K$59) -> 31 | M6: =RANK(K6,$K$3:$K$953) -> 519 | N6: A+ | O6: 市区统招生
A7: 20180354 | B7: 1801 | C7: 180105 | D7: 陈晔 | E7: 111 | F7: 109 | G7: 120 | H7: 50 | I7: 78 | J7: 65 | K7: =SUM(E7:J7) -> 533 | L7: =RANK(K7,$K$3:$K$59) -> 22 | M7: =RANK(K7,$K$3:$K$953) -> 415 | N7: A+ | O7: 市区外公费
A8: 20180757 | B8: 1801 | C8: 180106 | D8: 陈奕安 | E8: 119 | F8: 85 | G8: 125 | H8: 77 | I8: 90 | J8: 83 | K8: =SUM(E8:J8) -> 579 | L8: =RANK(K8,$K$3:$K$59) -> 5 | M8: =RANK(K8,$K$3:$K$953) -> 188 | N8: A+ | O8: 市区统招生
A9: 20180633 | B9: 1801 | C9: 180107 | D9: 方勇 | E9: 92 | F9: 61 | G9: 62 | H9: 64 | I9: 54 | J9: 46 | K9: =SUM(E9:J9) -> 379 | L9: =RANK(K9,$K$3:$K$59) -> 56 | M9: =RANK(K9,$K$3:$K$953) -> 942 | N9: A | O9: 市区统招生
A10: 20180155 | B10: 1801 | C10: 180108 | D10: 冯展明 | E10: 103 | F10: 97 | G10: 119.5 | H10: 62 | I10: 70 | J10: 67 | K10: =SUM(E10:J10) -> 518.5 | L10: =RANK(K10,$K$3:$K$59) -> 29 | M10: =RANK(K10,$K$3:$K$953) -> 514 | N10: A+ | O10: 计划生
A11: 20180009 | B11: 1801 | C11: 180109 | D11: 郭柳炎 | E11: 101 | F11: 101 | G11: 89.5 | H11: 66 | I11: 91 | J11: 74 | K11: =SUM(E11:J11) -> 522.5 | L11: =RANK(K11,$K$3:$K$59) -> 26 | M11: =RANK(K11,$K$3:$K$953) -> 488 | N11: A+ | O11: 市区外公费
A12: 20180115 | B12: 1801 | C12: 180110 | D12: 韩耀鑫 | E12: 101 | F12: 102 | G12: 94 | H12: 58 | I12: 79 | J12: 71 | K12: =SUM(E12:J12) -> 505 | L12: =RANK(K12,$K$3:$K$59) -> 36 | M12: =RANK(K12,$K$3:$K$953) -> 606 | N12: A | O12: 计划生
A13: 20180908 | B13: 1801 | C13: 180111 | D13: 何东泽 | E13: 114 | F13: 110 | G13: 90.5 | H13: 66 | I13: 82 | J13: 80 | K13: =SUM(E13:J13) -> 542.5 | L13: =RANK(K13,$K$3:$K$59) -> 17 | M13: =RANK(K13,$K$3:$K$953) -> 365 | N13: A | O13: 市区统招生
A14: 20180740 | B14: 1801 | C14: 180112 | D14: 胡锦鸿 | E14: 112 | F14: 99 | G14: 72.5 | H14: 84 | I14: 86 | J14: 72 | K14: =SUM(E14:J14) -> 525.5 | L14: =RANK(K14,$K$3:$K$59) -> 25 | M14: =RANK(K14,$K$3:$K$953) -> 466 | N14: A | O14: 市区统招生
A15: 20180510 | B15: 1801 | C15: 180113 | D15: 胡宗兰 | E15: 113 | F15: 113 | G15: 104 | H15: 81 | I15: 85 | J15: 81 | K15: =SUM(E15:J15) -> 577 | L15: =RANK(K15,$K$3:$K$59) -> 6 | M15: =RANK(K15,$K$3:$K$953) -> 197 | O15: 市区外公费
A16: 20180810 | B16: 1801 | C16: 180114 | D16: 黄柏淳 | E16: 90 | F16: 72 | G16: 118 | H16: 63 | I16: 72 | J16: 66 | K16: =SUM(E16:J16) -> 481 | L16: =RANK(K16,$K$3:$K$59) -> 42 | M16: =RANK(K16,$K$3:$K$953) -> 736 | N16: A | O16: 市区统招生
A17: 20180647 | B17: 1801 | C17: 180115 | D17: 黄嘉辉 | E17: 109 | F17: 99 | G17: 130.5 | H17: 63 | I17: 89 | J17: 73 | K17: =SUM(E17:J17) -> 563.5 | L17: =RANK(K17,$K$3:$K$59) -> 12 | M17: =RANK(K17,$K$3:$K$953) -> 263 | N17: A | O17: 市区统招生
A18: 20180595 | B18: 1801 | C18: 180116 | D18: 黄靖恒 | E18: 106 | F18: 94 | G18: 100 | H18: 64 | I18: 91 | J18: 67 | K18: =SUM(E18:J18) -> 522 | L18: =RANK(K18,$K$3:$K$59) -> 27 | M18: =RANK(K18,$K$3:$K$953) -> 491 | N18: A+ | O18: 市区统招生
A19: 20180162 | B19: 1801 | C19: 180117 | D19: 黄清枫 | E19: 112 | F19: 90 | G19: 114.5 | H19: 64 | I19: 77 | J19: 73 | K19: =SUM(E19:J19) -> 530.5 | L19: =RANK(K19,$K$3:$K$59) -> 23 | M19: =RANK(K19,$K$3:$K$953) -> 432 | N19: A+ | O19: 计划生
A20: 20180677 | B20: 1801 | C20: 180118 | D20: 黄诗淇 | E20: 104 | F20: 56 | G20: 112 | H20: 58 | I20: 83 | J20: 62 | K20: =SUM(E20:J20) -> 475 | L20: =RANK(K20,$K$3:$K$59) -> 44 | M20: =RANK(K20,$K$3:$K$953) -> 756 | N20: A | O20: 市区统招生
A21: 20180982 | B21: 1801 | C21: 180119 | D21: 黄昕玥 | E21: 99 | F21: 80 | G21: 100.5 | H21: 56 | I21: 85 | J21: 34 | K21: =SUM(E21:J21) -> 454.5 | L21: =RANK(K21,$K$3:$K$59) -> 49 | M21: =RANK(K21,$K$3:$K$953) -> 829 | N21: A | O21: 市区统招生
A22: 20180044 | B22: 1801 | C22: 180120 | D22: 蒋虹秀 | E22: 87 | F22: 46 | G22: 81.5 | H22: 11 | I22: 78 | J22: 39 | K22: =SUM(E22:J22) -> 342.5 | L22: =RANK(K22,$K$3:$K$59) -> 57 | M22: =RANK(K22,$K$3:$K$953) -> 949 | N22: A+ | O22: 计划生
A23: 20180153 | B23: 1801 | C23: 180121 | D23: 黎桁孜 | E23: 102 | F23: 91 | G23: 124 | H23: 65 | I23: 78 | J23: 55 | K23: =SUM(E23:J23) -> 515 | L23: =RANK(K23,$K$3:$K$59) -> 32 | M23: =RANK(K23,$K$3:$K$953) -> 542 | N23: A+ | O23: 计划生
A24: 20180556 | B24: 1801 | C24: 180122 | D24: 黎淼 | E24: 101 | F24: 99 | G24: 97 | H24: 66 | I24: 76 | J24: 76 | K24: =SUM(E24:J24) -> 515 | L24: =RANK(K24,$K$3:$K$59) -> 32 | M24: =RANK(K24,$K$3:$K$953) -> 542 | N24: A+ | O24: 市区统招生
A25: 20180482 | B25: 1801 | C25: 180123 | D25: 李媚 | E25: 110 | F25: 101 | G25: 108 | H25: 75 | I25: 85 | J25: 86 | K25: =SUM(E25:J25) -> 565 | L25: =RANK(K25,$K$3:$K$59) -> 11 | M25: =RANK(K25,$K$3:$K$953) -> 256 | N25: A+ | O25: 市区外公费
A26: 20181001 | B26: 1801 | C26: 180124 | D26: 李喜钊 | E26: 74 | F26: 80 | G26: 58 | H26: 49 | I26: 76 | J26: 62 | K26: =SUM(E26:J26) -> 399 | L26: =RANK(K26,$K$3:$K$59) -> 55 | M26: =RANK(K26,$K$3:$K$953) -> 930 | N26: A | O26: 市区统招生
A27: 20180553 | B27: 1801 | C27: 180125 | D27: 李星怡 | E27: 95 | F27: 102 | G27: 105.5 | H27: 74 | I27: 86 | J27: 76 | K27: =SUM(E27:J27) -> 538.5 | L27: =RANK(K27,$K$3:$K$59) -> 19 | M27: =RANK(K27,$K$3:$K$953) -> 388 | N27: A+ | O27: 市区外公费
... A59: 20180361 | B59: 1801 | C59: 180157 | D59: 周兴铖 | E59: 106 | F59: 116 | G59: 104.5 | H59: 74 | I59: 92 | J59: 78 | K59: =SUM(E59:J59) -> 570.5 | L59: =RANK(K59,$K$3:$K$59) -> 8 | M59: =RANK(K59,$K$3:$K$953) -> 233 | N59: A+ | O59: 市区外公费
A60: 20180111 | B60: 1802 | C60: 180201 | D60: 陈敏 | E60: 114 | F60: 103 | G60: 98.5 | H60: 69 | I60: 83 | J60: 71 | K60: =SUM(E60:J60) -> 538.5 | L60: =RANK(K60,$K$60:$K$116) -> 19 | M60: =RANK(K60,$K$3:$K$953) -> 388 | N60: A+ | O60: 计划生
A61: 20180710 | B61: 1802 | C61: 180202 | D61: 陈诗莜 | E61: 106 | F61: 98 | G61: 112 | H61: 59 | I61: 87 | J61: 66 | K61: =SUM(E61:J61) -> 528 | L61: =RANK(K61,$K$60:$K$116) -> 24 | M61: =RANK(K61,$K$3:$K$953) -> 449 | N61: A+ | O61: 市区统招生
A62: 20180261 | B62: 1802 | C62: 180203 | D62: 陈伊铭 | E62: 105 | F62: 116 | G62: 126 | H62: 67 | I62: 87 | J62: 85 | K62: =SUM(E62:J62) -> 586 | L62: =RANK(K62,$K$60:$K$116) -> 9 | M62: =RANK(K62,$K$3:$K$953) -> 158 | N62: A+ | O62: 计划生
A63: 20180582 | B63: 1802 | C63: 180204 | D63: 陈卓斌 | E63: 103 | F63: 77 | G63: 88 | H63: 74 | I63: 86 | J63: 87 | K63: =SUM(E63:J63) -> 515 | L63: =RANK(K63,$K$60:$K$116) -> 33 | M63: =RANK(K63,$K$3:$K$953) -> 542 | N63: A | O63: 市区统招生
A64: 20180404 | B64: 1802 | C64: 180205 | D64: 邓广英 | E64: 96 | F64: 85 | G64: 107.5 | H64: 60 | I64: 66 | J64: 82 | K64: =SUM(E64:J64) -> 496.5 | L64: =RANK(K64,$K$60:$K$116) -> 40 | M64: =RANK(K64,$K$3:$K$953) -> 660 | O64: 市区外公费
A65: 20180822 | B65: 1802 | C65: 180206 | D65: 方仕锋 | E65: 118 | F65: 138 | G65: 113.5 | H65: 89 | I65: 91 | J65: 87 | K65: =SUM(E65:J65) -> 636.5 | L65: =RANK(K65,$K$60:$K$116) -> 3 | M65: =RANK(K65,$K$3:$K$953) -> 27 | N65: A+ | O65: 市区统招生
A66: 20180541 | B66: 1802 | C66: 180207 | D66: 黄椿菱 | E66: 92 | F66: 83 | G66: 81 | H66: 58 | I66: 87 | J66: 62 | K66: =SUM(E66:J66) -> 463 | L66: =RANK(K66,$K$60:$K$116) -> 46 | M66: =RANK(K66,$K$3:$K$953) -> 808 | N66: A+ | O66: 市区外公费
A67: 20180220 | B67: 1802 | C67: 180208 | D67: 黄俊 | E67: 98 | F67: 58 | G67: 91 | H67: 57 | I67: 78 | J67: 56 | K67: =SUM(E67:J67) -> 438 | L67: =RANK(K67,$K$60:$K$116) -> 51 | M67: =RANK(K67,$K$3:$K$953) -> 870 | N67: A+ | O67: 市区外公费
A68: 20181038 | B68: 1802 | C68: 180209 | D68: 黄曦逸 | E68: 103 | F68: 109 | G68: 108 | H68: 50 | I68: 77 | J68: 71 | K68: =SUM(E68:J68) -> 518 | L68: =RANK(K68,$K$60:$K$116) -> 31 | M68: =RANK(K68,$K$3:$K$953) -> 516 | N68: A+ | O68: 市区统招生
A69: 20180847 | B69: 1802 | C69: 180210 | D69: 黄小桐 | E69: 103 | F69: 56 | G69: 101 | H69: 47 | I69: 64 | J69: 59 | K69: =SUM(E69:J69) -> 430 | L69: =RANK(K69,$K$60:$K$116) -> 53 | M69: =RANK(K69,$K$3:$K$953) -> 886 | N69: A | O69: 市区统招生
A70: 20181039 | B70: 1802 | C70: 180211 | D70: 黄修治 | E70: 104 | F70: 107 | G70: 93 | H70: 56 | I70: 88 | J70: 71 | K70: =SUM(E70:J70) -> 519 | L70: =RANK(K70,$K$60:$K$116) -> 30 | M70: =RANK(K70,$K$3:$K$953) -> 509 | N70: A+ | O70: 市区统招生
A71: 20180599 | B71: 1802 | C71: 180212 | D71: 黄颖茵 | E71: 114 | F71: 75 | G71: 92.5 | H71: 49 | I71: 73 | J71: 51 | K71: =SUM(E71:J71) -> 454.5 | L71: =RANK(K71,$K$60:$K$116) -> 49 | M71: =RANK(K71,$K$3:$K$953) -> 829 | N71: A | O71: 市区统招生
...

Sheet 统计表
A1: 高一年级1801-1820班月考（1）统计表 20181017
A2: 科目 | B2: 班别 | C2: 1801班 | D2: 1802班 | E2: 1803班 | F2: 1804班 | G2: 1805班 | H2: 1806班 | I2: 1807班 | J2: 1808班 | K2: 1809班 | L2: 1810班 | M2: 1811班 | N2: 1812班 | O2: 1813班 | P2: 1814班 | Q2: 1815班 | R2: 1816班 | S2: 1817班 | T2: 理科年级 | U2: 1818班 | V2: 1819班 | W2: 1820班 | X2: 文科年级
A3: 语文 / 150 | B3: 任课教师 | C3: 赵立田 | D3: 韩洁莹 | E3: 邓惠方 | F3: 唐明映 | G3: 吕韵 | H3: 吕韵 | I3: 周莉 | J3: 罗仲威 | K3: 姚明霞 | L3: 姚明霞 | M3: 夏琼妮 | N3: 夏琼妮 | O3: 朱巧红 | P3: 朱巧红 | Q3: 王东海 | R3: 赵立田 | S3: 梁彩玲 | U3: 龙辛夷 | V3: 唐明映 | W3: 龙辛夷
B4: 平均分 | C4: =AVERAGE(总表!E3:E59) -> 100.89474 | D4: =AVERAGE(总表!E60:E116) -> 105.7193 | E4: =AVERAGE(总表!E117:E173) -> 107.14035 | F4: =AVERAGE(总表!E174:E230) -> 101.94737 | G4: =AVERAGE(总表!E231:E286) -> 107.57143 | H4: =AVERAGE(总表!E287:E343) -> 108.94737 | I4: =AVERAGE(总表!E344:E400) -> 104.82456 | J4: =AVERAGE(总表!E401:E457) -> 104.63158 | K4: =AVERAGE(总表!E458:E507) -> 114.82 | L4: =AVERAGE(总表!E508:E559) -> 111.17308 | M4: =AVERAGE(总表!E560:E616) -> 104.42105 | N4: =AVERAGE(总表!E617:E672) -> 106.92857 | O4: =AVERAGE(总表!E673:E728) -> 104.07143 | P4: =AVERAGE(总表!E729:E784) -> 104.83929 | Q4: =AVERAGE(总表!E785:E840) -> 106.42857 | R4: =AVERAGE(总表!E841:E896) -> 102.19643 | S4: =AVERAGE(总表!E897:E953) -> 106.7193 | T4: =AVERAGE(总表!E3:E953) -> 105.98843 | U4: =AVERAGE(总表!E954:E1005) -> 114.13462 | V4: =AVERAGE(总表!E1006:E1039) -> 107.29412 | W4: =AVERAGE(总表!E1040:E1073) -> 107.82353 | X4: =AVERAGE(总表!E954:E1073) -> 110.40833
B5: 各班名次 | C5: =RANK(C4,$C$4:$S$4) -> 17 | D5: =RANK(D4,$C$4:$S$4) -> 9 | E5: =RANK(E4,$C$4:$S$4) -> 5 | F5: =RANK(F4,$C$4:$S$4) -> 16 | G5: =RANK(G4,$C$4:$S$4) -> 4 | H5: =RANK(H4,$C$4:$S$4) -> 3 | I5: =RANK(I4,$C$4:$S$4) -> 11 | J5: =RANK(J4,$C$4:$S$4) -> 12 | ... S5: =RANK(S4,$C$4:$S$4) -> 7 | U5: =RANK(U4,$U$4:$W$4) -> 1 | V5: =RANK(V4,$U$4:$W$4) -> 3 | W5: =RANK(W4,$U$4:$W$4) -> 2
B6: 优秀率 | C6: =COUNTIF(总表!E3:E59,">=120")/COUNTIF(总表!E3:E59,">=0") -> 0 | D6: =COUNTIF(总表!E60:E116,">=120")/COUNTIF(总表!E60:E116,">=0") -> 0.01754386 | E6: =COUNTIF(总表!E117:E173,">=120")/COUNTIF(总表!E117:E173,">=0") -> 0.035087719 | F6: =COUNTIF(总表!E174:E230,">=120")/COUNTIF(总表!E174:E230,">=0") -> 0 | G6: =COUNTIF(总表!E231:E286,">=120")/COUNTIF(总表!E231:E286,">=0") -> 0.053571429 | H6: =COUNTIF(总表!E287:E343,">=120")/COUNTIF(总表!E287:E343,">=0") -> 0.035087719 | I6: =COUNTIF(总表!E344:E400,">=120")/COUNTIF(总表!E344:E400,">=0") -> 0.070175439 | J6: =COUNTIF(总表!E401:E457,">=120")/COUNTIF(总表!E401:E457,">=0") -> 0.01754386 | K6: =COUNTIF(总表!E458:E507,">=120")/COUNTIF(总表!E458:E507,">=0") -> 0.28 | L6: =COUNTIF(总表!E508:E559,">=120")/COUNTIF(总表!E508:E559,">=0") -> 0.11538462 | M6: =COUNTIF(总表!E560:E616,">=120")/COUNTIF(总表!E560:E616,">=0") -> 0.035087719 | N6: =COUNTIF(总表!E617:E672,">=120")/COUNTIF(总表!E617:E672,">=0") -> 0.017857143 | O6: =COUNTIF(总表!E673:E728,">=120")/COUNTIF(总表!E673:E728,">=0") -> 0.017857143 | P6: =COUNTIF(总表!E729:E784,">=120")/COUNTIF(总表!E729:E784,">=0") -> 0.089285714 | Q6: =COUNTIF(总表!E785:E840,">=120")/COUNTIF(总表!E785:E840,">=0") -> 0.053571429 | R6: =COUNTIF(总表!E841:E896,">=120")/COUNTIF(总表!E841:E896,">=0") -> 0.017857143 | S6: =COUNTIF(总表!E897:E953,">=120")/COUNTIF(总表!E897:E953,">=0") -> 0.070175439 | T6: =COUNTIF(总表!E3:E953,">=120")/COUNTIF(总表!E3:E953,">=0") -> 0.052576236 | U6: =COUNTIF(总表!E954:E1005,">=120")/COUNTIF(总表!E954:E1005,">=0") -> 0.25 | V6: =COUNTIF(总表!E1006:E1039,">=120")/COUNTIF(总表!E1006:E1039,">=0") -> 0.11764706 | W6: =COUNTIF(总表!E1040:E1073,">=120")/COUNTIF(总表!E1040:E1073,">=0") -> 0.088235294 | X6: =COUNTIF(总表!E954:E1073,">=120")/COUNTIF(总表!E954:E1073,">=0") -> 0.16666667
B7: 及格率 | C7: =COUNTIF(总表!E3:E59,">=90")/COUNTIF(总表!E3:E59,">=0") -> 0.89473684 | D7: =COUNTIF(总表!E60:E116,">=90")/COUNTIF(总表!E60:E116,">=0") -> 0.94736842 | E7: =COUNTIF(总表!E117:E173,">=90")/COUNTIF(总表!E117:E173,">=0") -> 1 | F7: =COUNTIF(总表!E174:E230,">=90")/COUNTIF(总表!E174:E230,">=0") -> 0.89473684 | G7: =COUNTIF(总表!E231:E286,">=90")/COUNTIF(总表!E231:E286,">=0") -> 0.98214286 | H7: =COUNTIF(总表!E287:E343,">=90")/COUNTIF(总表!E287:E343,">=0") -> 0.98245614 | I7: =COUNTIF(总表!E344:E400,">=90")/COUNTIF(总表!E344:E400,">=0") -> 0.89473684 | J7: =COUNTIF(总表!E401:E457,">=90")/COUNTIF(总表!E401:E457,">=0") -> 0.92982456 | K7: =COUNTIF(总表!E458:E507,">=90")/COUNTIF(总表!E458:E507,">=0") -> 1 | L7: =COUNTIF(总表!E508:E559,">=90")/COUNTIF(总表!E508:E559,">=0") -> 1 | M7: =COUNTIF(总表!E560:E616,">=90")/COUNTIF(总表!E560:E616,">=0") -> 0.94736842 | N7: =COUNTIF(总表!E617:E672,">=90")/COUNTIF(总表!E617:E672,">=0") -> 1 | O7: =COUNTIF(总表!E673:E728,">=90")/COUNTIF(总表!E673:E728,">=0") -> 0.94642857 | P7: =COUNTIF(总表!E729:E784,">=90")/COUNTIF(总表!E729:E784,">=0") -> 0.91071429 | Q7: =COUNTIF(总表!E785:E840,">=90")/COUNTIF(总表!E785:E840,">=0") -> 0.96428571 | R7: =COUNTIF(总表!E841:E896,">=90")/COUNTIF(总表!E841:E896,">=0") -> 0.96428571 | S7: =COUNTIF(总表!E897:E953,">=90")/COUNTIF(总表!E897:E953,">=0") -> 0.98245614 | T7: =COUNTIF(总表!E3:E953,">=90")/COUNTIF(总表!E3:E953,">=0") -> 0.95478444 | U7: =COUNTIF(总表!E954:E1005,">=90")/COUNTIF(总表!E954:E1005,">=0") -> 1 | V7: =COUNTIF(总表!E1006:E1039,">=90")/COUNTIF(总表!E1006:E1039,">=0") -> 0.97058824 | W7: =COUNTIF(总表!E1040:E1073,">=90")/COUNTIF(总表!E1040:E1073,">=0") -> 0.97058824 | X7: =COUNTIF(总表!E954:E1073,">=90")/COUNTIF(总表!E954:E1073,">=0") -> 0.98333333
B8: 及格率名次 | C8: =RANK(C7,$C$7:$S$7) -> 15 | D8: =RANK(D7,$C$7:$S$7) -> 10 | E8: =RANK(E7,$C$7:$S$7) -> 1 | F8: =RANK(F7,$C$7:$S$7) -> 15 | G8: =RANK(G7,$C$7:$S$7) -> 7 | H8: =RANK(H7,$C$7:$S$7) -> 5 | I8: =RANK(I7,$C$7:$S$7) -> 15 | J8: =RANK(J7,$C$7:$S$7) -> 13 | ... S8: =RANK(S7,$C$7:$S$7) -> 5 | U8: =RANK(U7,$U$7:$W$7) -> 1 | V8: =RANK(V7,$U$7:$W$7) -> 2 | W8: =RANK(W7,$U$7:$W$7) -> 2
A9: 数学 / 150 | B9: 任课教师 | C9: 杨丽 | D9: 杨丽 | E9: 彭宝娟 | F9: 彭宝娟 | G9: 苏昊 | H9: 苏昊 | I9: 张立丽 | J9: 张立丽 | K9: 谭远森 | L9: 杨春兰 | M9: 彭乾 | N9: 彭乾 | O9: 陈珍妮 | P9: 陈珍妮 | Q9: 童碧斌 | R9: 周勇 | S9: 周勇 | U9: 左荣梅 | V9: 左荣梅 | W9: 童碧斌
B10: 平均分 | C10: =AVERAGE(总表!F3:F59) -> 93.824561 | D10: =AVERAGE(总表!F60:F116) -> 94.421053 | E10: =AVERAGE(总表!F117:F173) -> 98.929825 | F10: =AVERAGE(总表!F174:F230) -> 101.50877 | G10: =AVERAGE(总表!F231:F286) -> 88.964286 | H10: =AVERAGE(总表!F287:F343) -> 90.245614 | I10: =AVERAGE(总表!F344:F400) -> 95.245614 | J10: =AVERAGE(总表!F401:F457) -> 92.631579 | K10: =AVERAGE(总表!F458:F507) -> 121.14 | L10: =AVERAGE(总表!F508:F559) -> 108.09615 | M10: =AVERAGE(总表!F560:F616) -> 94.245614 | N10: =AVERAGE(总表!F617:F672) -> 94.25 | O10: =AVERAGE(总表!F673:F728) -> 88.803571 | P10: =AVERAGE(总表!F729:F784) -> 94.196429 | Q10: =AVERAGE(总表!F785:F840) -> 95.660714 | R10: =AVERAGE(总表!F841:F896) -> 93.178571 | S10: =AVERAGE(总表!F897:F953) -> 89.298246 | T10: =AVERAGE(总表!F3:F953) -> 95.931651 | U10: =AVERAGE(总表!F954:F1005) -> 93.442308 | V10: =AVERAGE(总表!F1006:F1039) -> 64.264706 | W10: =AVERAGE(总表!F1040:F1073) -> 67.058824 | X10: =AVERAGE(总表!F954:F1073) -> 77.7
B11: 各班名次 | C11: =RANK(C10,$C$10:$S$10) -> 11 | D11: =RANK(D10,$C$10:$S$10) -> 7 | E11: =RANK(E10,$C$10:$S$10) -> 4 | F11: =RANK(F10,$C$10:$S$10) -> 3 | G11: =RANK(G10,$C$10:$S$10) -> 16 | H11: =RANK(H10,$C$10:$S$10) -> 14 | I11: =RANK(I10,$C$10:$S$10) -> 6 | J11: =RANK(J10,$C$10:$S$10) -> 13 | ... S11: =RANK(S10,$C$10:$S$10) -> 15 | U11: =RANK(U10,$U$10:$W$10) -> 1 | V11: =RANK(V10,$U$10:$W$10) -> 3 | W11: =RANK(W10,$U$10:$W$10) -> 2
B12: 优秀率 | C12: =COUNTIF(总表!F3:F59,">=120")/COUNTIF(总表!F3:F59,">=0") -> 0.087719298 | D12: =COUNTIF(总表!F60:F116,">=120")/COUNTIF(总表!F60:F116,">=0") -> 0.14035088 | E12: =COUNTIF(总表!F117:F173,">=120")/COUNTIF(总表!F117:F173,">=0") -> 0.14035088 | F12: =COUNTIF(总表!F174:F230,">=120")/COUNTIF(总表!F174:F230,">=0") -> 0.22807018 | G12: =COUNTIF(总表!F231:F286,">=120")/COUNTIF(总表!F231:F286,">=0") -> 0.10714286 | H12: =COUNTIF(总表!F287:F343,">=120")/COUNTIF(总表!F287:F343,">=0") -> 0.10526316 | I12: =COUNTIF(总表!F344:F400,">=120")/COUNTIF(总表!F344:F400,">=0") -> 0.10526316 | J12: =COUNTIF(总表!F401:F457,">=120")/COUNTIF(总表!F401:F457,">=0") -> 0.12280702 | K12: =COUNTIF(总表!F458:F507,">=120")/COUNTIF(总表!F458:F507,">=0") -> 0.6 | L12: =COUNTIF(总表!F508:F559,">=120")/COUNTIF(总表!F508:F559,">=0") -> 0.26923077 | M12: =COUNTIF(总表!F560:F616,">=120")/COUNTIF(总表!F560:F616,">=0") -> 0.10526316 | N12: =COUNTIF(总表!F617:F672,">=120")/COUNTIF(总表!F617:F672,">=0") -> 0.14285714 | O12: =COUNTIF(总表!F673:F728,">=120")/COUNTIF(总表!F673:F728,">=0") -> 0.089285714 | P12: =COUNTIF(总表!F729:F784,">=120")/COUNTIF(总表!F729:F784,">=0") -> 0.16071429 | Q12: =COUNTIF(总表!F785:F840,">=120")/COUNTIF(总表!F785:F840,">=0") -> 0.071428571 | R12: =COUNTIF(总表!F841:F896,">=120")/COUNTIF(总表!F841:F896,">=0") -> 0.19642857 | S12: =COUNTIF(总表!F897:F953,">=120")/COUNTIF(总表!F897:F953,">=0") -> 0.12280702 | T12: =COUNTIF(总表!F3:F953,">=120")/COUNTIF(总表!F3:F953,">=0") -> 0.16088328 | U12: =COUNTIF(总表!F954:F1005,">=120")/COUNTIF(总表!F954:F1005,">=0") -> 0.096153846 | V12: =COUNTIF(总表!F1006:F1039,">=120")/COUNTIF(总表!F1006:F1039,">=0") -> 0 | W12: =COUNTIF(总表!F1040:F1073,">=120")/COUNTIF(总表!F1040:F1073,">=0") -> 0 | X12: =COUNTIF(总表!F954:F1073,">=120")/COUNTIF(总表!F954:F1073,">=0") -> 0.041666667
B13: 及格率 | C13: =COUNTIF(总表!F3:F59,">=90")/COUNTIF(总表!F3:F59,">=0") -> 0.61403509 | D13: =COUNTIF(总表!F60:F116,">=90")/COUNTIF(总表!F60:F116,">=0") -> 0.56140351 | E13: =COUNTIF(总表!F117:F173,">=90")/COUNTIF(总表!F117:F173,">=0") -> 0.68421053 | F13: =COUNTIF(总表!F174:F230,">=90")/COUNTIF(总表!F174:F230,">=0") -> 0.71929825 | G13: =COUNTIF(总表!F231:F286,">=90")/COUNTIF(总表!F231:F286,">=0") -> 0.51785714 | H13: =COUNTIF(总表!F287:F343,">=90")/COUNTIF(总表!F287:F343,">=0") -> 0.54385965 | I13: =COUNTIF(总表!F344:F400,">=90")/COUNTIF(总表!F344:F400,">=0") -> 0.66666667 | J13: =COUNTIF(总表!F401:F457,">=90")/COUNTIF(总表!F401:F457,">=0") -> 0.54385965 | K13: =COUNTIF(总表!F458:F507,">=90")/COUNTIF(总表!F458:F507,">=0") -> 1 | L13: =COUNTIF(总表!F508:F559,">=90")/COUNTIF(总表!F508:F559,">=0") -> 0.90384615 | M13: =COUNTIF(总表!F560:F616,">=90")/COUNTIF(总表!F560:F616,">=0") -> 0.56140351 | N13: =COUNTIF(总表!F617:F672,">=90")/COUNTIF(总表!F617:F672,">=0") -> 0.57142857 | O13: =COUNTIF(总表!F673:F728,">=90")/COUNTIF(总表!F673:F728,">=0") -> 0.5 | P13: =COUNTIF(总表!F729:F784,">=90")/COUNTIF(总表!F729:F784,">=0") -> 0.55357143 | Q13: =COUNTIF(总表!F785:F840,">=90")/COUNTIF(总表!F785:F840,">=0") -> 0.60714286 | R13: =COUNTIF(总表!F841:F896,">=90")/COUNTIF(总表!F841:F896,">=0") -> 0.58928571 | S13: =COUNTIF(总表!F897:F953,">=90")/COUNTIF(总表!F897:F953,">=0") -> 0.42105263 | T13: =COUNTIF(总表!F3:F953,">=90")/COUNTIF(总表!F3:F953,">=0") -> 0.61724501 | U13: =COUNTIF(总表!F954:F1005,">=90")/COUNTIF(总表!F954:F1005,">=0") -> 0.53846154 | V13: =COUNTIF(总表!F1006:F1039,">=90")/COUNTIF(总表!F1006:F1039,">=0") -> 0.11764706 | W13: =COUNTIF(总表!F1040:F1073,">=90")/COUNTIF(总表!F1040:F1073,">=0") -> 0.088235294 | X13: =COUNTIF(总表!F954:F1073,">=90")/COUNTIF(总表!F954:F1073,">=0") -> 0.29166667
B14: 及格率名次 | C14: =RANK(C13,$C$13:$S$13) -> 6 | D14: =RANK(D13,$C$13:$S$13) -> 10 | E14: =RANK(E13,$C$13:$S$13) -> 4 | F14: =RANK(F13,$C$13:$S$13) -> 3 | G14: =RANK(G13,$C$13:$S$13) -> 15 | H14: =RANK(H13,$C$13:$S$13) -> 13 | I14: =RANK(I13,$C$13:$S$13) -> 5 | J14: =RANK(J13,$C$13:$S$13) -> 13 | ... S14: =RANK(S13,$C$13:$S$13) -> 17 | U14: =RANK(U13,$U$13:$W$13) -> 1 | V14: =RANK(V13,$U$13:$W$13) -> 2 | W14: =RANK(W13,$U$13:$W$13) -> 3
A15: 英语 / 150 | B15: 任课教师 | C15: 邹瑶 | D15: 邹瑶 | E15: 陈柳燕 | F15: 李泉波 | G15: 叶彦灵 | H15: 叶彦灵 | I15: 陈清倩 | J15: 陈清倩 | K15: 陈丽文 | L15: 陈丽文 | M15: 彭湘玲 | N15: 彭湘玲 | O15: 陈东 | P15: 何忠林 | Q15: 关宁 | R15: 卢珊 | S15: 卢珊 | U15: 钟海妮 | V15: 杨君妮 | W15: 杨君妮
B16: 平均分 | C16: =AVERAGE(总表!G3:G59) -> 103.61404 | D16: =AVERAGE(总表!G60:G116) -> 105.75439 | E16: =AVERAGE(总表!G117:G173) -> 107.10526 | F16: =AVERAGE(总表!G174:G230) -> 104.4386 | G16: =AVERAGE(总表!G231:G286) -> 105.8125 | H16: =AVERAGE(总表!G287:G343) -> 104.03509 | I16: =AVERAGE(总表!G344:G400) -> 103.07018 | J16: =AVERAGE(总表!G401:G457) -> 104.31579 | K16: =AVERAGE(总表!G458:G507) -> 125.01 | L16: =AVERAGE(总表!G508:G559) -> 116.32692 | M16: =AVERAGE(总表!G560:G616) -> 108.19298 | N16: =AVERAGE(总表!G617:G672) -> 107.05357 | O16: =AVERAGE(总表!G673:G728) -> 107.52679 | P16: =AVERAGE(总表!G729:G784) -> 109.05357 | Q16: =AVERAGE(总表!G785:G840) -> 107.74107 | R16: =AVERAGE(总表!G841:G896) -> 108.04464 | S16: =AVERAGE(总表!G897:G953) -> 105.55263 | T16: =AVERAGE(总表!G3:G953) -> 107.63302 | U16: =AVERAGE(总表!G954:G1005) -> 119.60577 | V16: =AVERAGE(总表!G1006:G1039) -> 106.80882 | W16: =AVERAGE(总表!G1040:G1073) -> 110.27941 | X16: =AVERAGE(总表!G954:G1073) -> 113.3375
B17: 各班名次 | C17: =RANK(C16,$C$16:$S$16) -> 16 | D17: =RANK(D16,$C$16:$S$16) -> 11 | E17: =RANK(E16,$C$16:$S$16) -> 8 | F17: =RANK(F16,$C$16:$S$16) -> 13 | G17: =RANK(G16,$C$16:$S$16) -> 10 | H17: =RANK(H16,$C$16:$S$16) -> 15 | I17: =RANK(I16,$C$16:$S$16) -> 17 | J17: =RANK(J16,$C$16:$S$16) -> 14 | ... S17: =RANK(S16,$C$16:$S$16) -> 12 | U17: =RANK(U16,$U$16:$W$16) -> 1 | V17: =RANK(V16,$U$16:$W$16) -> 3 | W17: =RANK(W16,$U$16:$W$16) -> 2
B18: 优秀率 | C18: =COUNTIF(总表!G3:G59,">=120")/COUNTIF(总表!G3:G59,">=0") -> 0.1754386 | D18: =COUNTIF(总表!G60:G116,">=120")/COUNTIF(总表!G60:G116,">=0") -> 0.21052632 | E18: =COUNTIF(总表!G117:G173,">=120")/COUNTIF(总表!G117:G173,">=0") -> 0.21052632 | F18: =COUNTIF(总表!G174:G230,">=120")/COUNTIF(总表!G174:G230,">=0") -> 0.19298246 | G18: =COUNTIF(总表!G231:G286,">=120")/COUNTIF(总表!G231:G286,">=0") -> 0.26785714 | H18: =COUNTIF(总表!G287:G343,">=120")/COUNTIF(总表!G287:G343,">=0") -> 0.1754386 | I18: =COUNTIF(总表!G344:G400,">=120")/COUNTIF(总表!G344:G400,">=0") -> 0.14035088 | J18: =COUNTIF(总表!G401:G457,">=120")/COUNTIF(总表!G401:G457,">=0") -> 0.19298246 | K18: =COUNTIF(总表!G458:G507,">=120")/COUNTIF(总表!G458:G507,">=0") -> 0.82 | L18: =COUNTIF(总表!G508:G559,">=120")/COUNTIF(总表!G508:G559,">=0") -> 0.36538462 | M18: =COUNTIF(总表!G560:G616,">=120")/COUNTIF(总表!G560:G616,">=0") -> 0.1754386 | N18: =COUNTIF(总表!G617:G672,">=120")/COUNTIF(总表!G617:G672,">=0") -> 0.19642857 | O18: =COUNTIF(总表!G673:G728,">=120")/COUNTIF(总表!G673:G728,">=0") -> 0.25 | P18: =COUNTIF(总表!G729:G784,">=120")/COUNTIF(总表!G729:G784,">=0") -> 0.19642857 | Q18: =COUNTIF(总表!G785:G840,">=120")/COUNTIF(总表!G785:G840,">=0") -> 0.23214286 | R18: =COUNTIF(总表!G841:G896,">=120")/COUNTIF(总表!G841:G896,">=0") -> 0.21428571 | S18: =COUNTIF(总表!G897:G953,">=120")/COUNTIF(总表!G897:G953,">=0") -> 0.14035088 | T18: =COUNTIF(总表!G3:G953,">=120")/COUNTIF(总表!G3:G953,">=0") -> 0.23974763 | U18: =COUNTIF(总表!G954:G1005,">=120")/COUNTIF(总表!G954:G1005,">=0") -> 0.57692308 | V18: =COUNTIF(总表!G1006:G1039,">=120")/COUNTIF(总表!G1006:G1039,">=0") -> 0.17647059 | W18: =COUNTIF(总表!G1040:G1073,">=120")/COUNTIF(总表!G1040:G1073,">=0") -> 0.26470588 | X18: =COUNTIF(总表!G954:G1073,">=120")/COUNTIF(总表!G954:G1073,">=0") -> 0.375
B19: 及格率 | C19: =COUNTIF(总表!G3:G59,">=90")/COUNTIF(总表!G3:G59,">=0") -> 0.80701754 | D19: =COUNTIF(总表!G60:G116,">=90")/COUNTIF(总表!G60:G116,">=0") -> 0.85964912 | E19: =COUNTIF(总表!G117:G173,">=90")/COUNTIF(总表!G117:G173,">=0") -> 0.84210526 | F19: =COUNTIF(总表!G174:G230,">=90")/COUNTIF(总表!G174:G230,">=0") -> 0.80701754 | G19: =COUNTIF(总表!G231:G286,">=90")/COUNTIF(总表!G231:G286,">=0") -> 0.83928571 | H19: =COUNTIF(总表!G287:G343,">=90")/COUNTIF(总表!G287:G343,">=0") -> 0.87719298 | I19: =COUNTIF(总表!G344:G400,">=90")/COUNTIF(总表!G344:G400,">=0") -> 0.84210526 | J19: =COUNTIF(总表!G401:G457,">=90")/COUNTIF(总表!G401:G457,">=0") -> 0.75438596 | K19: =COUNTIF(总表!G458:G507,">=90")/COUNTIF(总表!G458:G507,">=0") -> 1 | L19: =COUNTIF(总表!G508:G559,">=90")/COUNTIF(总表!G508:G559,">=0") -> 1 | M19: =COUNTIF(总表!G560:G616,">=90")/COUNTIF(总表!G560:G616,">=0") -> 0.92982456 | N19: =COUNTIF(总表!G617:G672,">=90")/COUNTIF(总表!G617:G672,">=0") -> 0.89285714 | O19: =COUNTIF(总表!G673:G728,">=90")/COUNTIF(总表!G673:G728,">=0") -> 0.89285714 | P19: =COUNTIF(总表!G729:G784,">=90")/COUNTIF(总表!G729:G784,">=0") -> 0.89285714 | Q19: =COUNTIF(总表!G785:G840,">=90")/COUNTIF(总表!G785:G840,">=0") -> 0.875 | R19: =COUNTIF(总表!G841:G896,">=90")/COUNTIF(总表!G841:G896,">=0") -> 0.94642857 | S19: =COUNTIF(总表!G897:G953,">=90")/COUNTIF(总表!G897:G953,">=0") -> 0.89473684 | T19: =COUNTIF(总表!G3:G953,">=90")/COUNTIF(总表!G3:G953,">=0") -> 0.87802313 | U19: =COUNTIF(总表!G954:G1005,">=90")/COUNTIF(总表!G954:G1005,">=0") -> 0.96153846 | V19: =COUNTIF(总表!G1006:G1039,">=90")/COUNTIF(总表!G1006:G1039,">=0") -> 0.97058824 | W19: =COUNTIF(总表!G1040:G1073,">=90")/COUNTIF(总表!G1040:G1073,">=0") -> 0.94117647 | X19: =COUNTIF(总表!G954:G1073,">=90")/COUNTIF(总表!G954:G1073,">=0") -> 0.95833333
B20: 及格率名次 | C20: =RANK(C19,$C$19:$S$19) -> 15 | D20: =RANK(D19,$C$19:$S$19) -> 11 | E20: =RANK(E19,$C$19:$S$19) -> 12 | F20: =RANK(F19,$C$19:$S$19) -> 15 | G20: =RANK(G19,$C$19:$S$19) -> 14 | H20: =RANK(H19,$C$19:$S$19) -> 9 | I20: =RANK(I19,$C$19:$S$19) -> 12 | J20: =RANK(J19,$C$19:$S$19) -> 17 | ... S20: =RANK(S19,$C$19:$S$19) -> 5 | U20: =RANK(U19,$U$19:$W$19) -> 2 | V20: =RANK(V19,$U$19:$W$19) -> 1 | W20: =RANK(W19,$U$19:$W$19) -> 3
A21: 物理110/政治100 | B21: 任课教师 | C21: 崔影杏 | D21: 崔影杏 | E21: 崔影杏 | F21: 孙绍华 | G21: 孙绍华 | H21: 孙绍华 | I21: 杨镇泽 | J21: 杨镇泽 | K21: 周刚 | L21: 周刚 | M21: 林惠贞 | N21: 阳辉 | O21: 阳辉 | P21: 阳辉 | Q21: 杨镇泽 | R21: 庞丽萍 | S21: 庞丽萍 | U21: 刘涛 | V21: 邱裕玲 | W21: 刘涛
B22: 平均分 | C22: =AVERAGE(总表!H3:H59) -> 65.596491 | D22: =AVERAGE(总表!H60:H116) -> 64.701754 | E22: =AVERAGE(总表!H117:H173) -> 68.508772 | F22: =AVERAGE(总表!H174:H230) -> 64.245614 | G22: =AVERAGE(总表!H231:H286) -> 64.928571 | H22: =AVERAGE(总表!H287:H343) -> 64.894737 | I22: =AVERAGE(总表!H344:H400) -> 66.912281 | J22: =AVERAGE(总表!H401:H457) -> 67.508772 | K22: =AVERAGE(总表!H458:H507) -> 86.96 | L22: =AVERAGE(总表!H508:H559) -> 74.134615 | M22: =AVERAGE(总表!H560:H616) -> 67.877193 | N22: =AVERAGE(总表!H617:H672) -> 67.089286 | O22: =AVERAGE(总表!H673:H728) -> 64.321429 | P22: =AVERAGE(总表!H729:H784) -> 68.285714 | Q22: =AVERAGE(总表!H785:H840) -> 68.071429 | R22: =AVERAGE(总表!H841:H896) -> 67.25 | S22: =AVERAGE(总表!H897:H953) -> 66.649123 | T22: =AVERAGE(总表!H3:H953) -> 67.952681 | U22: =AVERAGE(总表!H954:H1005) -> 78.923077 | V22: =AVERAGE(总表!H1006:H1039) -> 73.852941 | W22: =AVERAGE(总表!H1040:H1073) -> 73 | X22: =AVERAGE(总表!H954:H1073) -> 75.808333
B23: 各班名次 | C23: =RANK(C22,$C$22:$S$22) -> 12 | D23: =RANK(D22,$C$22:$S$22) -> 15 | E23: =RANK(E22,$C$22:$S$22) -> 3 | F23: =RANK(F22,$C$22:$S$22) -> 17 | G23: =RANK(G22,$C$22:$S$22) -> 13 | H23: =RANK(H22,$C$22:$S$22) -> 14 | I23: =RANK(I22,$C$22:$S$22) -> 10 | J23: =RANK(J22,$C$22:$S$22) -> 7 | ... S23: =RANK(S22,$C$22:$S$22) -> 11 | U23: =RANK(U22,$U$22:$W$22) -> 1 | V23: =RANK(V22,$U$22:$W$22) -> 2 | W23: =RANK(W22,$U$22:$W$22) -> 3
B24: 优秀率 | C24: =COUNTIF(总表!H3:H59,">=88")/COUNTIF(总表!H3:H59,">=0") -> 0.052631579 | D24: =COUNTIF(总表!H60:H116,">=88")/COUNTIF(总表!H60:H116,">=0") -> 0.10526316 | E24: =COUNTIF(总表!H117:H173,">=88")/COUNTIF(总表!H117:H173,">=0") -> 0.070175439 | F24: =COUNTIF(总表!H174:H230,">=88")/COUNTIF(总表!H174:H230,">=0") -> 0.01754386 | G24: =COUNTIF(总表!H231:H286,">=88")/COUNTIF(总表!H231:H286,">=0") -> 0.053571429 | H24: =COUNTIF(总表!H287:H343,">=88")/COUNTIF(总表!H287:H343,">=0") -> 0.087719298 | I24: =COUNTIF(总表!H344:H400,">=88")/COUNTIF(总表!H344:H400,">=0") -> 0.12280702 | J24: =COUNTIF(总表!H401:H457,">=88")/COUNTIF(总表!H401:H457,">=0") -> 0.087719298 | K24: =COUNTIF(总表!H458:H507,">=88")/COUNTIF(总表!H458:H507,">=0") -> 0.48 | L24: =COUNTIF(总表!H508:H559,">=88")/COUNTIF(总表!H508:H559,">=0") -> 0.13461538 | M24: =COUNTIF(总表!H560:H616,">=88")/COUNTIF(总表!H560:H616,">=0") -> 0.070175439 | N24: =COUNTIF(总表!H617:H672,">=88")/COUNTIF(总表!H617:H672,">=0") -> 0.089285714 | O24: =COUNTIF(总表!H673:H728,">=88")/COUNTIF(总表!H673:H728,">=0") -> 0.053571429 | P24: =COUNTIF(总表!H729:H784,">=88")/COUNTIF(总表!H729:H784,">=0") -> 0.071428571 | Q24: =COUNTIF(总表!H785:H840,">=88")/COUNTIF(总表!H785:H840,">=0") -> 0.071428571 | R24: =COUNTIF(总表!H841:H896,">=88")/COUNTIF(总表!H841:H896,">=0") -> 0.053571429 | S24: =COUNTIF(总表!H897:H953,">=88")/COUNTIF(总表!H897:H953,">=0") -> 0.052631579 | T24: =COUNTIF(总表!H3:H953,">=88")/COUNTIF(总表!H3:H953,">=0") -> 0.095688749 | U24: =COUNTIF(总表!H954:H1005,">=80")/COUNTIF(总表!H954:H1005,">=0") -> 0.46153846 | V24: =COUNTIF(总表!H1006:H1039,">=80")/COUNTIF(总表!H1006:H1039,">=0") -> 0.17647059 | W24: =COUNTIF(总表!H1040:H1073,">=80")/COUNTIF(总表!H1040:H1073,">=0") -> 0.11764706 | X24: =COUNTIF(总表!H954:H1073,">=80")/COUNTIF(总表!H954:H1073,">=0") -> 0.28333333
